Workbook

Sheet Inicio
A1: REGISTRO DE COMISIONES DE SERVICIOS SIN RMU — SEPS
A2: Otorgadas hacia otras instituciones del Estado | Control de límite legal (LOSEP: máx. 6 años fuera de la institución)
A4: Panel de control
B6: =COUNTA('Base de Personas'!B7:B21) -> 15 | D6: =COUNTIF('Base de Personas'!T7:T21,"*VENCIDA*")+COUNTIF('Base de Personas'!T7:T21,"*VENCE PRONTO*") -> 7 | F6: =COUNTIF('Base de Personas'!R7:R21,"*SUPERO*")+COUNTIF('Base de Personas'!R7:R21,"*PROXIMO*") -> 0
B9: Personas en comisión | D9: Comisiones vencidas o por vencer (≤90 días) | F9: Cerca o sobre el límite legal de 6 años
B10: =COUNTIF('Base de Personas'!V7:V21,"*INACTIVO*")+COUNTIF('Base de Personas'!V7:V21,"*SIN REGISTRAR*") -> 6 | D10: =SUM('Base de Personas'!I7:I21) -> 20243 | F10: =SUMPRODUCT((COUNTIF('Base de Personas'!J7:J21,'Base de Personas'!J7:J21)=1)*1) -> 11
B13: Partidas con servidor inactivo/sin registrar | D13: RMU mensual total comprometido (referencial) | F13: Instituciones distintas receptoras
A15: Cómo usar este libro
A17: 1. Base de Personas | C17: Una fila por servidor público en comisión. Use el cuadro de búsqueda (celda C4 de esa hoja) para escribir cédula o nombre: las filas coincidentes se resaltan en amarillo. También puede usar las flechas de filtro de la tabla.
A18: 2. Detalle de Períodos | C18: Historial completo de cada renovación de comisión por persona (fecha de inicio y fin de cada período), base para los cálculos acumulados.
A19: 3. Estadísticas | C19: Indicadores y gráficos: distribución por institución, por grupo ocupacional, estado de comisiones y línea de tiempo (Gantt) de todas las comisiones vigentes.
A20: 4. Instrucciones y Macro VBA | C20: Guía de colores/semáforos y código VBA opcional para búsqueda rápida por InputBox y exportación automática de alertas.
A21: Alertas automáticas | C21: 🟢 Vigente / dentro del límite 🟡 Vigilar (≤1 año o ≤180 días) 🟠 Próximo a vencer (≤90–180 días) 🔴 Vencida o superó el límite legal de 6 años.
A22: Importante | C22: El "límite legal" se calcula sumando los días efectivos de comisión (columna "Días Acumulados") y proyectando 6 años desde la fecha de inicio de la primera comisión. Si la comisión tuvo interrupciones (regresos a la institución), revise manualmente la columna "Continuidad".

Sheet Base de Personas
A1: BASE DE PERSONAS EN COMISIÓN DE SERVICIOS SIN RMU
A2: Una fila por servidor público. Columnas J en adelante se calculan automáticamente a partir de la hoja "Detalle de Periodos".
A4: 🔍 Buscar (cédula o nombre): | I4: =IF($D$4="","Escriba un término para resaltar coincidencias en la tabla.","Coincidencias encontradas: "&(COUNTIF($B$7:$B$21,"*"&$D$4&"*")+COUNTIF($C$7:$C$21,"*"&$D$4&"*"))) -> Escriba un término para resaltar coincidencias en la tabla.
A6: No. | B6: Cédula | C6: Nombres Completos | D6: Ciudad | E6: Intendencia de Origen | F6: Dirección de Origen | G6: Cargo | H6: Grupo Ocupacional | I6: RMU | J6: Institución Actual (Destino) | K6: Fecha Inicio (1ra Comisión) | L6: Fecha Fin Comisión Actual | M6: N° Períodos /Renovaciones | N6: Días Acumulados en Comisión | O6: Años Acumulados (aprox.) | P6: Fecha Límite Legal (6 años) | Q6: Días Restantes al Límite Legal | R6: Estado Límite Legal (6 años) | S6: Días Restantes Comisión Actual | T6: Estado Comisión Actual | U6: Continuidad | V6: Servidor que Ocupa la Partida | W6: Dirección del Servidor que Ocupa
A7: 1 | B7: 1713260295 | C7: DUQUE VINUEZA GIOVANNY XAVIER | D7: QUITO | E7: INTENDENTE NACIONAL DE SUPERVISION A ORGANIZACIONES DE LA ECONOMIA POPULAR Y SOLIDARIA | F7: DIRECCION NACIONAL LEGAL DE ORGANIZACIONES DE LA ECONOMIA POPULAR Y SOLIDARIA | G7: ANALISTA JURIDICO 2 DE LA EPS | H7: SERVIDOR PUBLICO 7 | I7: 1676 | J7: =TRIM(SUBSTITUTE(SUBSTITUTE(SUBSTITUTE(SUBSTITUTE(SUBSTITUTE(SUBSTITUTE(UPPER(INDEX(tblPeriodos[Institución en el Período],MATCH(B7&"-1",tblPeriodos[Clave (uso interno)],0))),"Á","A"),"É","E"),"Í","I"),"Ó","O"),"Ú","U"),"Ü","U")) -> BANCO CENTRAL DEL ECUADOR | K7: =_xlfn.MINIFS(tblPeriodos[Fecha Inicio del Período],tblPeriodos[Cédula],B7) -> 44635 | L7: =_xlfn.MAXIFS(tblPeriodos[Fecha Fin del Período],tblPeriodos[Cédula],B7) -> 46460 | M7: =COUNTIFS(tblPeriodos[Cédula],B7) -> 4 | N7: =SUMIFS(tblPeriodos[Días del Período],tblPeriodos[Cédula],B7) -> 1827 | O7: =ROUND(N7/365.25,1) -> 5 | P7: =EDATE(K7,72) -> 46827 | Q7: =P7-TODAY() -> 553 | R7: =IF(Q7<=0,"🔴 SUPERO LIMITE LEGAL",IF(Q7<=180,"🟠 PROXIMO AL LIMITE (6 ANOS)",IF(Q7<=365,"🟡 VIGILAR (< 1 ANO)","🟢 DENTRO DEL LIMITE"))) -> 🟢 DENTRO DEL LIMITE | S7: =L7-TODAY() -> 186 | T7: =IF(S7<0,"🔴 COMISION VENCIDA",IF(S7<=90,"🟠 VENCE PRONTO (<=90 DIAS)",IF(S7<=180,"🟡 PROXIMA A VENCER (<=180 DIAS)","🟢 VIGENTE"))) -> 🟢 VIGENTE | U7: =IF(ABS(N7-(L7-K7+1))<=3,"CONTINUA","CON INTERRUPCIONES - REVISAR") -> CONTINUA | V7: =TRIM(SUBSTITUTE(SUBSTITUTE(SUBSTITUTE(SUBSTITUTE(SUBSTITUTE(SUBSTITUTE(UPPER(IFERROR(INDEX('Registro de Comisión'!$L$5:$L$304,MATCH($B7&"-ACT",'Registro de Comisión'!$N$5:$N$304,0)),"NEIRA TACURE ELIZABETH DEL CARMEN")),"Á","A"),"É","E"),"Í","I"),"Ó","O"),"Ú","U"),"Ü","U")) -> NEIRA TACURE ELIZABETH DEL CARMEN | W7: DIRECCION NACIONAL DE SUPERVISION A ENTIDADES DEL SECTOR FINANCIERO TIPO I
A8: 2 | B8: 1722632476 | C8: BARAHONA LOPEZ IVAN PATRICIO | D8: QUITO | E8: SECRETARIA GENERAL | F8: DIRECCION NACIONAL DE GESTION DOCUMENTAL Y ARCHIVO | G8: ASISTENTE TECNICO DE GESTION DOCUMENTAL | H8: SERVIDOR PUBLICO 1 | I8: 817 | J8: =TRIM(SUBSTITUTE(SUBSTITUTE(SUBSTITUTE(SUBSTITUTE(SUBSTITUTE(SUBSTITUTE(UPPER(INDEX(tblPeriodos[Institución en el Período],MATCH(B8&"-1",tblPeriodos[Clave (uso interno)],0))),"Á","A"),"É","E"),"Í","I"),"Ó","O"),"Ú","U"),"Ü","U")) -> BANCO CENTRAL DEL ECUADOR | K8: =_xlfn.MINIFS(tblPeriodos[Fecha Inicio del Período],tblPeriodos[Cédula],B8) -> 44697 | L8: =_xlfn.MAXIFS(tblPeriodos[Fecha Fin del Período],tblPeriodos[Cédula],B8) -> 46522 | M8: =COUNTIFS(tblPeriodos[Cédula],B8) -> 4 | N8: =SUMIFS(tblPeriodos[Días del Período],tblPeriodos[Cédula],B8) -> 1827 | O8: =ROUND(N8/365.25,1) -> 5 | P8: =EDATE(K8,72) -> 46889 | Q8: =P8-TODAY() -> 615 | R8: =IF(Q8<=0,"🔴 SUPERO LIMITE LEGAL",IF(Q8<=180,"🟠 PROXIMO AL LIMITE (6 ANOS)",IF(Q8<=365,"🟡 VIGILAR (< 1 ANO)","🟢 DENTRO DEL LIMITE"))) -> 🟢 DENTRO DEL LIMITE | S8: =L8-TODAY() -> 248 | T8: =IF(S8<0,"🔴 COMISION VENCIDA",IF(S8<=90,"🟠 VENCE PRONTO (<=90 DIAS)",IF(S8<=180,"🟡 PROXIMA A VENCER (<=180 DIAS)","🟢 VIGENTE"))) -> 🟢 VIGENTE | U8: =IF(ABS(N8-(L8-K8+1))<=3,"CONTINUA","CON INTERRUPCIONES - REVISAR") -> CONTINUA | V8: =TRIM(SUBSTITUTE(SUBSTITUTE(SUBSTITUTE(SUBSTITUTE(SUBSTITUTE(SUBSTITUTE(UPPER(IFERROR(INDEX('Registro de Comisión'!$L$5:$L$304,MATCH($B8&"-ACT",'Registro de Comisión'!$N$5:$N$304,0)),"MUÑOZ MOLINA WALTER ALEXIS")),"Á","A"),"É","E"),"Í","I"),"Ó","O"),"Ú","U"),"Ü","U")) -> MUÑOZ MOLINA WALTER ALEXIS | W8: INTENEDENCIA NACIONAL DE PLANIFICACION Y GESTION ESTRATEGICA / DIRECCION NCIONAL DE PROCESOS Y CALIDAD
A9: 3 | B9: 1721533576 | C9: TAPIA FLORES GARDENIA CECIBEL | D9: CUENCA | E9: DIRECCION ZONAL 5 | F9: UNIDAD DE SERVICIOS | G9: ASISTENTE DE GESTION DOCUMENTAL ZONAL | H9: SERVIDOR PUBLICO 1 | I9: 817 | J9: =TRIM(SUBSTITUTE(SUBSTITUTE(SUBSTITUTE(SUBSTITUTE(SUBSTITUTE(SUBSTITUTE(UPPER(INDEX(tblPeriodos[Institución en el Período],MATCH(B9&"-1",tblPeriodos[Clave (uso interno)],0))),"Á","A"),"É","E"),"Í","I"),"Ó","O"),"Ú","U"),"Ü","U")) -> GOBIERNO AUTONOMO DESENTRALZIADO, MUNICIPAL DEL CANTON SEVILLA DE ORO | K9: =_xlfn.MINIFS(tblPeriodos[Fecha Inicio del Período],tblPeriodos[Cédula],B9) -> 45075 | L9: =_xlfn.MAXIFS(tblPeriodos[Fecha Fin del Período],tblPeriodos[Cédula],B9) -> 46535 | M9: =COUNTIFS(tblPeriodos[Cédula],B9) -> 1 | N9: =SUMIFS(tblPeriodos[Días del Período],tblPeriodos[Cédula],B9) -> 1461 | O9: =ROUND(N9/365.25,1) -> 4 | P9: =EDATE(K9,72) -> 47267 | Q9: =P9-TODAY() -> 993 | R9: =IF(Q9<=0,"🔴 SUPERO LIMITE LEGAL",IF(Q9<=180,"🟠 PROXIMO AL LIMITE (6 ANOS)",IF(Q9<=365,"🟡 VIGILAR (< 1 ANO)","🟢 DENTRO DEL LIMITE"))) -> 🟢 DENTRO DEL LIMITE | S9: =L9-TODAY() -> 261 | T9: =IF(S9<0,"🔴 COMISION VENCIDA",IF(S9<=90,"🟠 VENCE PRONTO (<=90 DIAS)",IF(S9<=180,"🟡 PROXIMA A VENCER (<=180 DIAS)","🟢 VIGENTE"))) -> 🟢 VIGENTE | U9: =IF(ABS(N9-(L9-K9+1))<=3,"CONTINUA","CON INTERRUPCIONES - REVISAR") -> CONTINUA | V9: =TRIM(SUBSTITUTE(SUBSTITUTE(SUBSTITUTE(SUBSTITUTE(SUBSTITUTE(SUBSTITUTE(UPPER(IFERROR(INDEX('Registro de Comisión'!$L$5:$L$304,MATCH($B9&"-ACT",'Registro de Comisión'!$N$5:$N$304,0)),"BEDOYA PADILLA KEVIN ANDRES")),"Á","A"),"É","E"),"Í","I"),"Ó","O"),"Ú","U"),"Ü","U")) -> BEDOYA PADILLA KEVIN ANDRES | W9: DIRECCION NACIONAL DE ATENCION A CONSULTAS Y RECLAMOS DE LA ECONOMIA POPULAR Y SOLIDARIA
A10: 4 | B10: 1711688190 | C10: SANTAMARIA RUEDA DIEGO MAURICIO | D10: QUITO | E10: INTENDENCIA NACIONAL ADMINISTRATIVA FINANCIERA | F10: DIRECCION NACIONAL FINANCIERA | G10: ANALISTA DE TESORERIA 1 | H10: SERVIDOR PUBLICO 5 | I10: 1212 | J10: =TRIM(SUBSTITUTE(SUBSTITUTE(SUBSTITUTE(SUBSTITUTE(SUBSTITUTE(SUBSTITUTE(UPPER(INDEX(tblPeriodos[Institución en el Período],MATCH(B10&"-1",tblPeriodos[Clave (uso interno)],0))),"Á","A"),"É","E"),"Í","I"),"Ó","O"),"Ú","U"),"Ü","U")) -> GOBIERNO AUTONOMO DESCENTRALIZADO DEL DISTRITO METROPOLITANO DE QUITO | K10: =_xlfn.MINIFS(tblPeriodos[Fecha Inicio del Período],tblPeriodos[Cédula],B10) -> 45096 | L10: =_xlfn.MAXIFS(tblPeriodos[Fecha Fin del Período],tblPeriodos[Cédula],B10) -> 46203 | M10: =COUNTIFS(tblPeriodos[Cédula],B10) -> 2 | N10: =SUMIFS(tblPeriodos[Días del Período],tblPeriodos[Cédula],B10) -> 1108 | O10: =ROUND(N10/365.25,1) -> 3 | P10: =EDATE(K10,72) -> 47288 | Q10: =P10-TODAY() -> 1014 | R10: =IF(Q10<=0,"🔴 SUPERO LIMITE LEGAL",IF(Q10<=180,"🟠 PROXIMO AL LIMITE (6 ANOS)",IF(Q10<=365,"🟡 VIGILAR (< 1 ANO)","🟢 DENTRO DEL LIMITE"))) -> 🟢 DENTRO DEL LIMITE | S10: =L10-TODAY() -> -71 | T10: =IF(S10<0,"🔴 COMISION VENCIDA",IF(S10<=90,"🟠 VENCE PRONTO (<=90 DIAS)",IF(S10<=180,"🟡 PROXIMA A VENCER (<=180 DIAS)","🟢 VIGENTE"))) -> 🔴 COMISION VENCIDA | U10: =IF(ABS(N10-(L10-K10+1))<=3,"CONTINUA","CON INTERRUPCIONES - REVISAR") -> CONTINUA | V10: =TRIM(SUBSTITUTE(SUBSTITUTE(SUBSTITUTE(SUBSTITUTE(SUBSTITUTE(SUBSTITUTE(UPPER(IFERROR(INDEX('Registro de Comisión'!$L$5:$L$304,MATCH($B10&"-ACT",'Registro de Comisión'!$N$5:$N$304,0)),"MUÑOZ GARCIA DIANA PAMELA")),"Á","A"),"É","E"),"Í","I"),"Ó","O"),"Ú","U"),"Ü","U")) -> MUÑOZ GARCIA DIANA PAMELA | W10: DIRECCION NACIONAL FINANCIERA
A11: 5 | B11: 0917368417 | C11: GUERRERO FLORES LENCY WALKIRIA | D11: GUAYAQUIL | E11: DIRECCION ZONAL 5 | F11: UNIDAD DE SERVICIOS | G11: ANALISTA DE SERVICIO AL CIUDADANO ZONAL | H11: SERVIDOR PUBLICO 7 | I11: 1676 | J11: =TRIM(SUBSTITUTE(SUBSTITUTE(SUBSTITUTE(SUBSTITUTE(SUBSTITUTE(SUBSTITUTE(UPPER(INDEX(tblPeriodos[Institución en el Período],MATCH(B11&"-1",tblPeriodos[Clave (uso interno)],0))),"Á","A"),"É","E"),"Í","I"),"Ó","O"),"Ú","U"),"Ü","U")) -> CONTRALORIA GENERAL DEL ESTADO | K11: =_xlfn.MINIFS(tblPeriodos[Fecha Inicio del Período],tblPeriodos[Cédula],B11) -> 45323 | L11: =_xlfn.MAXIFS(tblPeriodos[Fecha Fin del Período],tblPeriodos[Cédula],B11) -> 46418 | M11: =COUNTIFS(tblPeriodos[Cédula],B11) -> 2 | N11: =SUMIFS(tblPeriodos[Días del Período],tblPeriodos[Cédula],B11) -> 1096 | O11: =ROUND(N11/365.25,1) -> 3 | P11: =EDATE(K11,72) -> 47515 | Q11: =P11-TODAY() -> 1241 | R11: =IF(Q11<=0,"🔴 SUPERO LIMITE LEGAL",IF(Q11<=180,"🟠 PROXIMO AL LIMITE (6 ANOS)",IF(Q11<=365,"🟡 VIGILAR (< 1 ANO)","🟢 DENTRO DEL LIMITE"))) -> 🟢 DENTRO DEL LIMITE | S11: =L11-TODAY() -> 144 | T11: =IF(S11<0,"🔴 COMISION VENCIDA",IF(S11<=90,"🟠 VENCE PRONTO (<=90 DIAS)",IF(S11<=180,"🟡 PROXIMA A VENCER (<=180 DIAS)","🟢 VIGENTE"))) -> 🟡 PROXIMA A VENCER (<=180 DIAS) | U11: =IF(ABS(N11-(L11-K11+1))<=3,"CONTINUA","CON INTERRUPCIONES - REVISAR") -> CONTINUA | V11: =TRIM(SUBSTITUTE(SUBSTITUTE(SUBSTITUTE(SUBSTITUTE(SUBSTITUTE(SUBSTITUTE(UPPER(IFERROR(INDEX('Registro de Comisión'!$L$5:$L$304,MATCH($B11&"-ACT",'Registro de Comisión'!$N$5:$N$304,0)),"ALBUJA QUINTANA RODRIGO ALEJANDRO")),"Á","A"),"É","E"),"Í","I"),"Ó","O"),"Ú","U"),"Ü","U")) -> ALBUJA QUINTANA RODRIGO ALEJANDRO | W11: DIRECCION NACIONAL DE GESTION DE SERVICIOS
A12: 6 | B12: 1716262728 | C12: ZAMORA CORDOVA FELIX WLADIMIR | D12: QUITO | E12: INTENDENCIA NACIONAL DE SUPERVISION A ENTIDADES DEL SECTOR FINANCIERO POPULAR Y SOLIDARIO | F12: DIRECCION NACIONAL LEGAL DEL SECTOR FINANCIERO | G12: ANALISTA LEGAL DEL SECTOR FINANCIERO 2 | H12: SERVIDOR PUBLICO 7 | I12: 1676 | J12: =TRIM(SUBSTITUTE(SUBSTITUTE(SUBSTITUTE(SUBSTITUTE(SUBSTITUTE(SUBSTITUTE(UPPER(INDEX(tblPeriodos[Institución en el Período],MATCH(B12&"-1",tblPeriodos[Clave (uso interno)],0))),"Á","A"),"É","E"),"Í","I"),"Ó","O"),"Ú","U"),"Ü","U")) -> SECRETARIA TECNICA DEL COMITE DE COORDINACION DE LA FUNCION DE TRANSPARENCIA Y CONTROL SOCIAL | K12: =_xlfn.MINIFS(tblPeriodos[Fecha Inicio del Período],tblPeriodos[Cédula],B12) -> 45573 | L12: =_xlfn.MAXIFS(tblPeriodos[Fecha Fin del Período],tblPeriodos[Cédula],B12) -> 46302 | M12: =COUNTIFS(tblPeriodos[Cédula],B12) -> 1 | N12: =SUMIFS(tblPeriodos[Días del Período],tblPeriodos[Cédula],B12) -> 730 | O12: =ROUND(N12/365.25,1) -> 2 | P12: =EDATE(K12,72) -> 47764 | Q12: =P12-TODAY() -> 1490 | R12: =IF(Q12<=0,"🔴 SUPERO LIMITE LEGAL",IF(Q12<=180,"🟠 PROXIMO AL LIMITE (6 ANOS)",IF(Q12<=365,"🟡 VIGILAR (< 1 ANO)","🟢 DENTRO DEL LIMITE"))) -> 🟢 DENTRO DEL LIMITE | S12: =L12-TODAY() -> 28 | T12: =IF(S12<0,"🔴 COMISION VENCIDA",IF(S12<=90,"🟠 VENCE PRONTO (<=90 DIAS)",IF(S12<=180,"🟡 PROXIMA A VENCER (<=180 DIAS)","🟢 VIGENTE"))) -> 🟠 VENCE PRONTO (<=90 DIAS) | U12: =IF(ABS(N12-(L12-K12+1))<=3,"CONTINUA","CON INTERRUPCIONES - REVISAR") -> CONTINUA | V12: =TRIM(SUBSTITUTE(SUBSTITUTE(SUBSTITUTE(SUBSTITUTE(SUBSTITUTE(SUBSTITUTE(UPPER(IFERROR(INDEX('Registro de Comisión'!$L$5:$L$304,MATCH($B12&"-ACT",'Registro de Comisión'!$N$5:$N$304,0)),"CAÑIZARES LARCO VICTORIA ELIZABETH")),"Á","A"),"É","E"),"Í","I"),"Ó","O"),"Ú","U"),"Ü","U")) -> CAÑIZARES LARCO VICTORIA ELIZABETH | W12: DIRECCION NACIONAL LEGAL DEL SECTOR FINANCIERO
A13: 7 | B13: 1712422839 | C13: LOYOLA TRONCOSO JAIME EDUARDO | D13: QUITO | E13: INTENDENCIA NACIONAL DE TECNOLOGIAS DE LA INFORMACION Y COMUNICACIONES | F13: DIRECCION NACIONAL DE INFRAESTRUCTURA TECNOLOGICA Y OPERACIONES | G13: ANALISTA EN ASEGURAMIENTO Y CONTROL DE LA CALIDAD DE TECNOLOGIAS DE INFORMACION 2 | H13: SERVIDOR PUBLICO 7 | I13: 1676 | J13: =TRIM(SUBSTITUTE(SUBSTITUTE(SUBSTITUTE(SUBSTITUTE(SUBSTITUTE(SUBSTITUTE(UPPER(INDEX(tblPeriodos[Institución en el Período],MATCH(B13&"-1",tblPeriodos[Clave (uso interno)],0))),"Á","A"),"É","E"),"Í","I"),"Ó","O"),"Ú","U"),"Ü","U")) -> ADMINISTRACION GENERAL DEL GAD DEL DISTRITO METROPOLITANO DE QUITO | K13: =_xlfn.MINIFS(tblPeriodos[Fecha Inicio del Período],tblPeriodos[Cédula],B13) -> 45658 | L13: =_xlfn.MAXIFS(tblPeriodos[Fecha Fin del Período],tblPeriodos[Cédula],B13) -> 46053 | M13: =COUNTIFS(tblPeriodos[Cédula],B13) -> 2 | N13: =SUMIFS(tblPeriodos[Días del Período],tblPeriodos[Cédula],B13) -> 396 | O13: =ROUND(N13/365.25,1) -> 1.1 | P13: =EDATE(K13,72) -> 47849 | Q13: =P13-TODAY() -> 1575 | R13: =IF(Q13<=0,"🔴 SUPERO LIMITE LEGAL",IF(Q13<=180,"🟠 PROXIMO AL LIMITE (6 ANOS)",IF(Q13<=365,"🟡 VIGILAR (< 1 ANO)","🟢 DENTRO DEL LIMITE"))) -> 🟢 DENTRO DEL LIMITE | S13: =L13-TODAY() -> -221 | T13: =IF(S13<0,"🔴 COMISION VENCIDA",IF(S13<=90,"🟠 VENCE PRONTO (<=90 DIAS)",IF(S13<=180,"🟡 PROXIMA A VENCER (<=180 DIAS)","🟢 VIGENTE"))) -> 🔴 COMISION VENCIDA | U13: =IF(ABS(N13-(L13-K13+1))<=3,"CONTINUA","CON INTERRUPCIONES - REVISAR") -> CONTINUA | V13: =TRIM(SUBSTITUTE(SUBSTITUTE(SUBSTITUTE(SUBSTITUTE(SUBSTITUTE(SUBSTITUTE(UPPER(IFERROR(INDEX('Registro de Comisión'!$L$5:$L$304,MATCH($B13&"-ACT",'Registro de Comisión'!$N$5:$N$304,0)),"CAIZA PILLAJO SAIRA LORENA")),"Á","A"),"É","E"),"Í","I"),"Ó","O"),"Ú","U"),"Ü","U")) -> CAIZA PILLAJO SAIRA LORENA | W13: DIRECCION NACIONAL DE INFRAESTRUCTURA TECNOLOGICA Y OPERACIONES
A14: 8 | B14: 1719201822 | C14: RACINES NUÑEZ MARIA DANIELA | D14: QUITO | E14: INTENDENCIA NACIONAL DE SUPERVISION A ENTIDADES DEL SECTOR FINANCIERO POPULAR Y SOLIDARIO | F14: DIRECCION NACIONAL DE SUPERVISION A ENTIDADES DEL SECTOR FINANCIERO TIPO I | G14: ANALISTA DE AUDITORIA DEL SECTOR FINANCIERO | H14: SERVIDOR PUBLICO 5 | I14: 1212 | J14: =TRIM(SUBSTITUTE(SUBSTITUTE(SUBSTITUTE(SUBSTITUTE(SUBSTITUTE(SUBSTITUTE(UPPER(INDEX(tblPeriodos[Institución en el Período],MATCH(B14&"-1",tblPeriodos[Clave (uso interno)],0))),"Á","A"),"É","E"),"Í","I"),"Ó","O"),"Ú","U"),"Ü","U")) -> SUPERINTENDENCIA DE BANCOS | K14: =_xlfn.MINIFS(tblPeriodos[Fecha Inicio del Período],tblPeriodos[Cédula],B14) -> 45992 | L14: =_xlfn.MAXIFS(tblPeriodos[Fecha Fin del Período],tblPeriodos[Cédula],B14) -> 46356 | M14: =COUNTIFS(tblPeriodos[Cédula],B14) -> 1 | N14: =SUMIFS(tblPeriodos[Días del Período],tblPeriodos[Cédula],B14) -> 365 | O14: =ROUND(N14/365.25,1) -> 1 | P14: =EDATE(K14,72) -> 48183 | Q14: =P14-TODAY() -> 1909 | R14: =IF(Q14<=0,"🔴 SUPERO LIMITE LEGAL",IF(Q14<=180,"🟠 PROXIMO AL LIMITE (6 ANOS)",IF(Q14<=365,"🟡 VIGILAR (< 1 ANO)","🟢 DENTRO DEL LIMITE"))) -> 🟢 DENTRO DEL LIMITE | S14: =L14-TODAY() -> 82 | T14: =IF(S14<0,"🔴 COMISION VENCIDA",IF(S14<=90,"🟠 VENCE PRONTO (<=90 DIAS)",IF(S14<=180,"🟡 PROXIMA A VENCER (<=180 DIAS)","🟢 VIGENTE"))) -> 🟠 VENCE PRONTO (<=90 DIAS) | U14: =IF(ABS(N14-(L14-K14+1))<=3,"CONTINUA","CON INTERRUPCIONES - REVISAR") -> CONTINUA | V14: =TRIM(SUBSTITUTE(SUBSTITUTE(SUBSTITUTE(SUBSTITUTE(SUBSTITUTE(SUBSTITUTE(UPPER(IFERROR(INDEX('Registro de Comisión'!$L$5:$L$304,MATCH($B14&"-ACT",'Registro de Comisión'!$N$5:$N$304,0)),"CHAUCA ORTEGA MARIA FERNANDA")),"Á","A"),"É","E"),"Í","I"),"Ó","O"),"Ú","U"),"Ü","U")) -> CHAUCA ORTEGA MARIA FERNANDA | W14: DIRECCION NACIONAL DE SUPERVISION A ENTIDADES DEL SECTOR FINANCIERO TIPO I
A15: 9 | B15: 1717835407 | C15: PALLARES CASTRO DARIO XAVIER | D15: QUITO | E15: INTENDENCIA NACIONAL ADMINISTRATIVA FINANCIERA | F15: DIRECCION NACIONAL ADMINISTRATIVA | G15: ANALISTA ADMINISTRATIVO DE SERVICIOS GENERALES | H15: SERVIDOR PUBLICO 7 | I15: 1676 | J15: =TRIM(SUBSTITUTE(SUBSTITUTE(SUBSTITUTE(SUBSTITUTE(SUBSTITUTE(SUBSTITUTE(UPPER(INDEX(tblPeriodos[Institución en el Período],MATCH(B15&"-1",tblPeriodos[Clave (uso interno)],0))),"Á","A"),"É","E"),"Í","I"),"Ó","O"),"Ú","U"),"Ü","U")) -> MINISTERIO DEL TRABAJO | K15: =_xlfn.MINIFS(tblPeriodos[Fecha Inicio del Período],tblPeriodos[Cédula],B15) -> 45689 | L15: =_xlfn.MAXIFS(tblPeriodos[Fecha Fin del Período],tblPeriodos[Cédula],B15) -> 46568 | M15: =COUNTIFS(tblPeriodos[Cédula],B15) -> 3 | N15: =SUMIFS(tblPeriodos[Días del Período],tblPeriodos[Cédula],B15) -> 786 | O15: =ROUND(N15/365.25,1) -> 2.2 | P15: =EDATE(K15,72) -> 47880 | Q15: =P15-TODAY() -> 1606 | R15: =IF(Q15<=0,"🔴 SUPERO LIMITE LEGAL",IF(Q15<=180,"🟠 PROXIMO AL LIMITE (6 ANOS)",IF(Q15<=365,"🟡 VIGILAR (< 1 ANO)","🟢 DENTRO DEL LIMITE"))) -> 🟢 DENTRO DEL LIMITE | S15: =L15-TODAY() -> 294 | T15: =IF(S15<0,"🔴 COMISION VENCIDA",IF(S15<=90,"🟠 VENCE PRONTO (<=90 DIAS)",IF(S15<=180,"🟡 PROXIMA A VENCER (<=180 DIAS)","🟢 VIGENTE"))) -> 🟢 VIGENTE | U15: =IF(ABS(N15-(L15-K15+1))<=3,"CONTINUA","CON INTERRUPCIONES - REVISAR") -> CON INTERRUPCIONES - REVISAR | V15: =TRIM(SUBSTITUTE(SUBSTITUTE(SUBSTITUTE(SUBSTITUTE(SUBSTITUTE(SUBSTITUTE(UPPER(IFERROR(INDEX('Registro de Comisión'!$L$5:$L$304,MATCH($B15&"-ACT",'Registro de Comisión'!$N$5:$N$304,0)),"ALVEAR VALDIVIESO BYRON RAMIRO")),"Á","A"),"É","E"),"Í","I"),"Ó","O"),"Ú","U"),"Ü","U")) -> ALVEAR VALDIVIESO BYRON RAMIRO | W15: DIRECCION NACIONAL ADMINISTRATIVA
A16: 10 | B16: 1718348913 | C16: BURBANO PALACIOS MARIA EUGENIA | D16: QUITO | E16: INTENDENCIA NACIONAL ADMINISTRATIVA FINANCIERA | F16: DIRECCION NACIONAL ADMINISTRATIVA | G16: ANALISTA DE COMPRAS | H16: SERVIDOR PUBLICO 5 | I16: 1212 | J16: =TRIM(SUBSTITUTE(SUBSTITUTE(SUBSTITUTE(SUBSTITUTE(SUBSTITUTE(SUBSTITUTE(UPPER(INDEX(tblPeriodos[Institución en el Período],MATCH(B16&"-1",tblPeriodos[Clave (uso interno)],0))),"Á","A"),"É","E"),"Í","I"),"Ó","O"),"Ú","U"),"Ü","U")) -> VICEPRESIDENCIA DE LA REPUBLICA DEL ECUADOR | K16: =_xlfn.MINIFS(tblPeriodos[Fecha Inicio del Período],tblPeriodos[Cédula],B16) -> 45689 | L16: =_xlfn.MAXIFS(tblPeriodos[Fecha Fin del Período],tblPeriodos[Cédula],B16) -> 46112 | M16: =COUNTIFS(tblPeriodos[Cédula],B16) -> 2 | N16: =SUMIFS(tblPeriodos[Días del Período],tblPeriodos[Cédula],B16) -> 421 | O16: =ROUND(N16/365.25,1) -> 1.2 | P16: =EDATE(K16,72) -> 47880 | Q16: =P16-TODAY() -> 1606 | R16: =IF(Q16<=0,"🔴 SUPERO LIMITE LEGAL",IF(Q16<=180,"🟠 PROXIMO AL LIMITE (6 ANOS)",IF(Q16<=365,"🟡 VIGILAR (< 1 ANO)","🟢 DENTRO DEL LIMITE"))) -> 🟢 DENTRO DEL LIMITE | S16: =L16-TODAY() -> -162 | T16: =IF(S16<0,"🔴 COMISION VENCIDA",IF(S16<=90,"🟠 VENCE PRONTO (<=90 DIAS)",IF(S16<=180,"🟡 PROXIMA A VENCER (<=180 DIAS)","🟢 VIGENTE"))) -> 🔴 COMISION VENCIDA | U16: =IF(ABS(N16-(L16-K16+1))<=3,"CONTINUA","CON INTERRUPCIONES - REVISAR") -> CONTINUA | V16: =TRIM(SUBSTITUTE(SUBSTITUTE(SUBSTITUTE(SUBSTITUTE(SUBSTITUTE(SUBSTITUTE(UPPER(IFERROR(INDEX('Registro de Comisión'!$L$5:$L$304,MATCH($B16&"-ACT",'Registro de Comisión'!$N$5:$N$304,0)),"INACTIVO TEMPORALMENTE")),"Á","A"),"É","E"),"Í","I"),"Ó","O"),"Ú","U"),"Ü","U")) -> INACTIVO TEMPORALMENTE | W16: INACTIVO TEMPORALMENTE
A17: 11 | B17: 1802226850 | C17: SALAZAR BERMEO TERESA ELIZABETH | D17: QUITO | E17: INTENDENCIA NACIONAL DE SUPERVISION A ORGANIZACIONES DE LA ECONOMIA POPULAR Y SOLIDARIA | F17: DIRECCION NACIONAL DE SUPERVISION A ORGANIZACIONES DE LA ECONOMIA POPULAR Y SOLIDARIA | G17: ANALISTA DE SUPERVISION AUXILIAR DE LA EPS 2 | H17: SERVIDOR PUBLICO 7 | I17: 1676 | J17: =TRIM(SUBSTITUTE(SUBSTITUTE(SUBSTITUTE(SUBSTITUTE(SUBSTITUTE(SUBSTITUTE(UPPER(INDEX(tblPeriodos[Institución en el Período],MATCH(B17&"-1",tblPeriodos[Clave (uso interno)],0))),"Á","A"),"É","E"),"Í","I"),"Ó","O"),"Ú","U"),"Ü","U")) -> EMPRESA PUBLICA DE HIDROCARBUROS DEL ECUADOR EP PETROECUADOR | K17: =_xlfn.MINIFS(tblPeriodos[Fecha Inicio del Período],tblPeriodos[Cédula],B17) -> 45978 | L17: =_xlfn.MAXIFS(tblPeriodos[Fecha Fin del Período],tblPeriodos[Cédula],B17) -> 46342 | M17: =COUNTIFS(tblPeriodos[Cédula],B17) -> 1 | N17: =SUMIFS(tblPeriodos[Días del Período],tblPeriodos[Cédula],B17) -> 365 | O17: =ROUND(N17/365.25,1) -> 1 | P17: =EDATE(K17,72) -> 48169 | Q17: =P17-TODAY() -> 1895 | R17: =IF(Q17<=0,"🔴 SUPERO LIMITE LEGAL",IF(Q17<=180,"🟠 PROXIMO AL LIMITE (6 ANOS)",IF(Q17<=365,"🟡 VIGILAR (< 1 ANO)","🟢 DENTRO DEL LIMITE"))) -> 🟢 DENTRO DEL LIMITE | S17: =L17-TODAY() -> 68 | T17: =IF(S17<0,"🔴 COMISION VENCIDA",IF(S17<=90,"🟠 VENCE PRONTO (<=90 DIAS)",IF(S17<=180,"🟡 PROXIMA A VENCER (<=180 DIAS)","🟢 VIGENTE"))) -> 🟠 VENCE PRONTO (<=90 DIAS) | U17: =IF(ABS(N17-(L17-K17+1))<=3,"CONTINUA","CON INTERRUPCIONES - REVISAR") -> CONTINUA | V17: =TRIM(SUBSTITUTE(SUBSTITUTE(SUBSTITUTE(SUBSTITUTE(SUBSTITUTE(SUBSTITUTE(UPPER(IFERROR(INDEX('Registro de Comisión'!$L$5:$L$304,MATCH($B17&"-ACT",'Registro de Comisión'!$N$5:$N$304,0)),"SIN REGISTRAR")),"Á","A"),"É","E"),"Í","I"),"Ó","O"),"Ú","U"),"Ü","U")) -> SIN REGISTRAR
A18: 12 | B18: 0302025838 | C18: CRESPO CARDENAS DAVID GERARDO | D18: CUENCA | E18: DIRECCION ZONAL 5 | F18: UNIDAD LEGAL DEL SECTOR FINANCIERO | G18: ANALISTA LEGAL DEL SECTOR FINANCIERO ZONAL 2 | H18: SERVIDOR PUBLICO 7 | I18: 1676 | J18: =TRIM(SUBSTITUTE(SUBSTITUTE(SUBSTITUTE(SUBSTITUTE(SUBSTITUTE(SUBSTITUTE(UPPER(INDEX(tblPeriodos[Institución en el Período],MATCH(B18&"-1",tblPeriodos[Clave (uso interno)],0))),"Á","A"),"É","E"),"Í","I"),"Ó","O"),"Ú","U"),"Ü","U")) -> GOBERNACION DE LA PROVINCIA DEL CAÑAR | K18: =_xlfn.MINIFS(tblPeriodos[Fecha Inicio del Período],tblPeriodos[Cédula],B18) -> 46013 | L18: =_xlfn.MAXIFS(tblPeriodos[Fecha Fin del Período],tblPeriodos[Cédula],B18) -> 46377 | M18: =COUNTIFS(tblPeriodos[Cédula],B18) -> 1 | N18: =SUMIFS(tblPeriodos[Días del Período],tblPeriodos[Cédula],B18) -> 365 | O18: =ROUND(N18/365.25,1) -> 1 | P18: =EDATE(K18,72) -> 48204 | Q18: =P18-TODAY() -> 1930 | R18: =IF(Q18<=0,"🔴 SUPERO LIMITE LEGAL",IF(Q18<=180,"🟠 PROXIMO AL LIMITE (6 ANOS)",IF(Q18<=365,"🟡 VIGILAR (< 1 ANO)","🟢 DENTRO DEL LIMITE"))) -> 🟢 DENTRO DEL LIMITE | S18: =L18-TODAY() -> 103 | T18: =IF(S18<0,"🔴 COMISION VENCIDA",IF(S18<=90,"🟠 VENCE PRONTO (<=90 DIAS)",IF(S18<=180,"🟡 PROXIMA A VENCER (<=180 DIAS)","🟢 VIGENTE"))) -> 🟡 PROXIMA A VENCER (<=180 DIAS) | U18: =IF(ABS(N18-(L18-K18+1))<=3,"CONTINUA","CON INTERRUPCIONES - REVISAR") -> CONTINUA | V18: =TRIM(SUBSTITUTE(SUBSTITUTE(SUBSTITUTE(SUBSTITUTE(SUBSTITUTE(SUBSTITUTE(UPPER(IFERROR(INDEX('Registro de Comisión'!$L$5:$L$304,MATCH($B18&"-ACT",'Registro de Comisión'!$N$5:$N$304,0)),"SIN REGISTRAR")),"Á","A"),"É","E"),"Í","I"),"Ó","O"),"Ú","U"),"Ü","U")) -> SIN REGISTRAR
A19: 13 | B19: 1715408819 | C19: BRICEÑO PILA ANA MARIA | D19: QUITO | E19: INTENDENCIA NACIONAL DE RIESGOS | F19: DIRECCION NACIONAL DE SEGUIMIENTO | G19: ANALISTA DE SUPERVISION AUXILIAR DE LA EPS 1 | H19: SERVIDOR PUBLICO 5 | I19: 1212 | J19: =TRIM(SUBSTITUTE(SUBSTITUTE(SUBSTITUTE(SUBSTITUTE(SUBSTITUTE(SUBSTITUTE(UPPER(INDEX(tblPeriodos[Institución en el Período],MATCH(B19&"-1",tblPeriodos[Clave (uso interno)],0))),"Á","A"),"É","E"),"Í","I"),"Ó","O"),"Ú","U"),"Ü","U")) -> EMPRESA PUBLICA DE HIDROCARBUROS DEL ECUADOR EP PETROECUADOR | K19: =_xlfn.MINIFS(tblPeriodos[Fecha Inicio del Período],tblPeriodos[Cédula],B19) -> 46113 | L19: =_xlfn.MAXIFS(tblPeriodos[Fecha Fin del Período],tblPeriodos[Cédula],B19) -> 46843 | M19: =COUNTIFS(tblPeriodos[Cédula],B19) -> 1 | N19: =SUMIFS(tblPeriodos[Días del Período],tblPeriodos[Cédula],B19) -> 731 | O19: =ROUND(N19/365.25,1) -> 2 | P19: =EDATE(K19,72) -> 48305 | Q19: =P19-TODAY() -> 2031 | R19: =IF(Q19<=0,"🔴 SUPERO LIMITE LEGAL",IF(Q19<=180,"🟠 PROXIMO AL LIMITE (6 ANOS)",IF(Q19<=365,"🟡 VIGILAR (< 1 ANO)","🟢 DENTRO DEL LIMITE"))) -> 🟢 DENTRO DEL LIMITE | S19: =L19-TODAY() -> 569 | T19: =IF(S19<0,"🔴 COMISION VENCIDA",IF(S19<=90,"🟠 VENCE PRONTO (<=90 DIAS)",IF(S19<=180,"🟡 PROXIMA A VENCER (<=180 DIAS)","🟢 VIGENTE"))) -> 🟢 VIGENTE | U19: =IF(ABS(N19-(L19-K19+1))<=3,"CONTINUA","CON INTERRUPCIONES - REVISAR") -> CONTINUA | V19: =TRIM(SUBSTITUTE(SUBSTITUTE(SUBSTITUTE(SUBSTITUTE(SUBSTITUTE(SUBSTITUTE(UPPER(IFERROR(INDEX('Registro de Comisión'!$L$5:$L$304,MATCH($B19&"-ACT",'Registro de Comisión'!$N$5:$N$304,0)),"SIN REGISTRAR")),"Á","A"),"É","E"),"Í","I"),"Ó","O"),"Ú","U"),"Ü","U")) -> SIN REGISTRAR
A20: 14 | B20: 1725390221 | C20: PAUCAR AREVALO JACQUELINE ESTEFANIA | D20: QUITO | E20: INTENDENCIA NACIONAL DE GESTION DE LA INFORMACION Y NORMATIVA TECNICA | F20: DIRECCION NACIONAL DE ESTUDIOS, DESARROLLO E INNOVACION | G20: ANALISTA DE INVESTIGACION Y CAPACITACION 1 | H20: SERVIDOR PUBLICO 5 | I20: 1212 | J20: =TRIM(SUBSTITUTE(SUBSTITUTE(SUBSTITUTE(SUBSTITUTE(SUBSTITUTE(SUBSTITUTE(UPPER(INDEX(tblPeriodos[Institución en el Período],MATCH(B20&"-1",tblPeriodos[Clave (uso interno)],0))),"Á","A"),"É","E"),"Í","I"),"Ó","O"),"Ú","U"),"Ü","U")) -> BANCO DEL INSTITUTO ECUATORIANO DE SEGURIDAD SOCIAL BIESS | K20: =_xlfn.MINIFS(tblPeriodos[Fecha Inicio del Período],tblPeriodos[Cédula],B20) -> 46113 | L20: =_xlfn.MAXIFS(tblPeriodos[Fecha Fin del Período],tblPeriodos[Cédula],B20) -> 46477 | M20: =COUNTIFS(tblPeriodos[Cédula],B20) -> 1 | N20: =SUMIFS(tblPeriodos[Días del Período],tblPeriodos[Cédula],B20) -> 365 | O20: =ROUND(N20/365.25,1) -> 1 | P20: =EDATE(K20,72) -> 48305 | Q20: =P20-TODAY() -> 2031 | R20: =IF(Q20<=0,"🔴 SUPERO LIMITE LEGAL",IF(Q20<=180,"🟠 PROXIMO AL LIMITE (6 ANOS)",IF(Q20<=365,"🟡 VIGILAR (< 1 ANO)","🟢 DENTRO DEL LIMITE"))) -> 🟢 DENTRO DEL LIMITE | S20: =L20-TODAY() -> 203 | T20: =IF(S20<0,"🔴 COMISION VENCIDA",IF(S20<=90,"🟠 VENCE PRONTO (<=90 DIAS)",IF(S20<=180,"🟡 PROXIMA A VENCER (<=180 DIAS)","🟢 VIGENTE"))) -> 🟢 VIGENTE | U20: =IF(ABS(N20-(L20-K20+1))<=3,"CONTINUA","CON INTERRUPCIONES - REVISAR") -> CONTINUA | V20: =TRIM(SUBSTITUTE(SUBSTITUTE(SUBSTITUTE(SUBSTITUTE(SUBSTITUTE(SUBSTITUTE(UPPER(IFERROR(INDEX('Registro de Comisión'!$L$5:$L$304,MATCH($B20&"-ACT",'Registro de Comisión'!$N$5:$N$304,0)),"SIN REGISTRAR")),"Á","A"),"É","E"),"Í","I"),"Ó","O"),"Ú","U"),"Ü","U")) -> SIN REGISTRAR
A21: 15 | B21: 1721084919 | C21: BEDON VELASCO KARINA SALOME | D21: QUITO | E21: INTENDENCIA NACIONAL ADMINISTRATIVA FINANCIERA | F21: DIRECCION NACIONAL ADMINISTRATIVA | G21: ASISTENTE DE COMPRAS PUBLICAS | H21: SERVIDOR PUBLICO 1 | I21: 817 | J21: =TRIM(SUBSTITUTE(SUBSTITUTE(SUBSTITUTE(SUBSTITUTE(SUBSTITUTE(SUBSTITUTE(UPPER(INDEX(tblPeriodos[Institución en el Período],MATCH(B21&"-1",tblPeriodos[Clave (uso interno)],0))),"Á","A"),"É","E"),"Í","I"),"Ó","O"),"Ú","U"),"Ü","U")) -> CONSORCIO DE GOBIERNOS AUTONOMOS PROVINCIALES DEL ECUADOR CONGOPE | K21: =_xlfn.MINIFS(tblPeriodos[Fecha Inicio del Período],tblPeriodos[Cédula],B21) -> 46132 | L21: =_xlfn.MAXIFS(tblPeriodos[Fecha Fin del Período],tblPeriodos[Cédula],B21) -> 46265 | M21: =COUNTIFS(tblPeriodos[Cédula],B21) -> 1 | N21: =SUMIFS(tblPeriodos[Días del Período],tblPeriodos[Cédula],B21) -> 134 | O21: =ROUND(N21/365.25,1) -> 0.4 | P21: =EDATE(K21,72) -> 48324 | Q21: =P21-TODAY() -> 2050 | R21: =IF(Q21<=0,"🔴 SUPERO LIMITE LEGAL",IF(Q21<=180,"🟠 PROXIMO AL LIMITE (6 ANOS)",IF(Q21<=365,"🟡 VIGILAR (< 1 ANO)","🟢 DENTRO DEL LIMITE"))) -> 🟢 DENTRO DEL LIMITE | S21: =L21-TODAY() -> -9 | T21: =IF(S21<0,"🔴 COMISION VENCIDA",IF(S21<=90,"🟠 VENCE PRONTO (<=90 DIAS)",IF(S21<=180,"🟡 PROXIMA A VENCER (<=180 DIAS)","🟢 VIGENTE"))) -> 🔴 COMISION VENCIDA | U21: =IF(ABS(N21-(L21-K21+1))<=3,"CONTINUA","CON INTERRUPCIONES - REVISAR") -> CONTINUA | V21: =TRIM(SUBSTITUTE(SUBSTITUTE(SUBSTITUTE(SUBSTITUTE(SUBSTITUTE(SUBSTITUTE(UPPER(IFERROR(INDEX('Registro de Comisión'!$L$5:$L$304,MATCH($B21&"-ACT",'Registro de Comisión'!$N$5:$N$304,0)),"SIN REGISTRAR")),"Á","A"),"É","E"),"Í","I"),"Ó","O"),"Ú","U"),"Ü","U")) -> SIN REGISTRAR
A22: =IF($B22="","",ROW()-6) | B22: =IFERROR(INDEX('Registro de Comisión'!$A$5:$A$304,MATCH(ROW()-21,'Registro de Comisión'!$P$5:$P$304,0)),"") | C22: =IF($B22="","",TRIM(SUBSTITUTE(SUBSTITUTE(SUBSTITUTE(SUBSTITUTE(SUBSTITUTE(SUBSTITUTE(UPPER(IFERROR(INDEX('Registro de Comisión'!$B$5:$B$304,MATCH(ROW()-21,'Registro de Comisión'!$P$5:$P$304,0)),"")),"Á","A"),"É","E"),"Í","I"),"Ó","O"),"Ú","U"),"Ü","U"))) | D22: =IF($B22="","",TRIM(SUBSTITUTE(SUBSTITUTE(SUBSTITUTE(SUBSTITUTE(SUBSTITUTE(SUBSTITUTE(UPPER(IFERROR(INDEX('Registro de Comisión'!$C$5:$C$304,MATCH(ROW()-21,'Registro de Comisión'!$P$5:$P$304,0)),"")),"Á","A"),"É","E"),"Í","I"),"Ó","O"),"Ú","U"),"Ü","U"))) | E22: =IF($B22="","",TRIM(SUBSTITUTE(SUBSTITUTE(SUBSTITUTE(SUBSTITUTE(SUBSTITUTE(SUBSTITUTE(UPPER(IFERROR(INDEX('Registro de Comisión'!$D$5:$D$304,MATCH(ROW()-21,'Registro de Comisión'!$P$5:$P$304,0)),"")),"Á","A"),"É","E"),"Í","I"),"Ó","O"),"Ú","U"),"Ü","U"))) | F22: =IF($B22="","",TRIM(SUBSTITUTE(SUBSTITUTE(SUBSTITUTE(SUBSTITUTE(SUBSTITUTE(SUBSTITUTE(UPPER(IFERROR(INDEX('Registro de Comisión'!$E$5:$E$304,MATCH(ROW()-21,'Registro de Comisión'!$P$5:$P$304,0)),"")),"Á","A"),"É","E"),"Í","I"),"Ó","O"),"Ú","U"),"Ü","U"))) | G22: =IF($B22="","",TRIM(SUBSTITUTE(SUBSTITUTE(SUBSTITUTE(SUBSTITUTE(SUBSTITUTE(SUBSTITUTE(UPPER(IFERROR(INDEX('Registro de Comisión'!$F$5:$F$304,MATCH(ROW()-21,'Registro de Comisión'!$P$5:$P$304,0)),"")),"Á","A"),"É","E"),"Í","I"),"Ó","O"),"Ú","U"),"Ü","U"))) | H22: =IF($B22="","",TRIM(SUBSTITUTE(SUBSTITUTE(SUBSTITUTE(SUBSTITUTE(SUBSTITUTE(SUBSTITUTE(UPPER(IFERROR(INDEX('Registro de Comisión'!$G$5:$G$304,MATCH(ROW()-21,'Registro de Comisión'!$P$5:$P$304,0)),"")),"Á","A"),"É","E"),"Í","I"),"Ó","O"),"Ú","U"),"Ü","U"))) | I22: =IF($B22="","",IFERROR(INDEX('Registro de Comisión'!$H$5:$H$304,MATCH(ROW()-21,'Registro de Comisión'!$P$5:$P$304,0)),"")) | J22: =IF($B22="","",TRIM(SUBSTITUTE(SUBSTITUTE(SUBSTITUTE(SUBSTITUTE(SUBSTITUTE(SUBSTITUTE(UPPER(IFERROR(INDEX(tblPeriodos[Institución en el Período],MATCH($B22&"-1",tblPeriodos[Clave (uso interno)],0)),"SIN PERIODO REGISTRADO")),"Á","A"),"É","E"),"Í","I"),"Ó","O"),"Ú","U"),"Ü","U"))) | K22: =IF($B22="","",IFERROR(_xlfn.MINIFS(tblPeriodos[Fecha Inicio del Período],tblPeriodos[Cédula],$B22),"")) | L22: =IF($B22="","",IFERROR(_xlfn.MAXIFS(tblPeriodos[Fecha Fin del Período],tblPeriodos[Cédula],$B22),"")) | M22: =IF($B22="","",COUNTIFS(tblPeriodos[Cédula],$B22)) | N22: =IF($B22="","",SUMIFS(tblPeriodos[Días del Período],tblPeriodos[Cédula],$B22)) | O22: =IF($B22="","",ROUND(N22/365.25,1)) | P22: =IF($B22="","",EDATE(K22,72)) | Q22: =IF($B22="","",P22-TODAY()) | R22: =IF($B22="","",IF(Q22<=0,"🔴 SUPERO LIMITE LEGAL",IF(Q22<=180,"🟠 PROXIMO AL LIMITE (6 ANOS)",IF(Q22<=365,"🟡 VIGILAR (< 1 ANO)","🟢 DENTRO DEL LIMITE")))) | S22: =IF($B22="","",L22-TODAY()) | T22: =IF($B22="","",IF(S22<0,"🔴 COMISION VENCIDA",IF(S22<=90,"🟠 VENCE PRONTO (<=90 DIAS)",IF(S22<=180,"🟡 PROXIMA A VENCER (<=180 DIAS)","🟢 VIGENTE")))) | U22: =IF($B22="","",IF(ABS(N22-(L22-K22+1))<=3,"CONTINUA","CON INTERRUPCIONES - REVISAR")) | V22: =IF($B22="","",TRIM(SUBSTITUTE(SUBSTITUTE(SUBSTITUTE(SUBSTITUTE(SUBSTITUTE(SUBSTITUTE(UPPER(IFERROR(INDEX('Registro de Comisión'!$L$5:$L$304,MATCH($B22&"-ACT",'Registro de Comisión'!$N$5:$N$304,0)),"SIN REGISTRAR")),"Á","A"),"É","E"),"Í","I"),"Ó","O"),"Ú","U"),"Ü","U")))
A23: =IF($B23="","",ROW()-6) | B23: =IFERROR(INDEX('Registro de Comisión'!$A$5:$A$304,MATCH(ROW()-21,'Registro de Comisión'!$P$5:$P$304,0)),"") | C23: =IF($B23="","",TRIM(SUBSTITUTE(SUBSTITUTE(SUBSTITUTE(SUBSTITUTE(SUBSTITUTE(SUBSTITUTE(UPPER(IFERROR(INDEX('Registro de Comisión'!$B$5:$B$304,MATCH(ROW()-21,'Registro de Comisión'!$P$5:$P$304,0)),"")),"Á","A"),"É","E"),"Í","I"),"Ó","O"),"Ú","U"),"Ü","U"))) | D23: =IF($B23="","",TRIM(SUBSTITUTE(SUBSTITUTE(SUBSTITUTE(SUBSTITUTE(SUBSTITUTE(SUBSTITUTE(UPPER(IFERROR(INDEX('Registro de Comisión'!$C$5:$C$304,MATCH(ROW()-21,'Registro de Comisión'!$P$5:$P$304,0)),"")),"Á","A"),"É","E"),"Í","I"),"Ó","O"),"Ú","U"),"Ü","U"))) | E23: =IF($B23="","",TRIM(SUBSTITUTE(SUBSTITUTE(SUBSTITUTE(SUBSTITUTE(SUBSTITUTE(SUBSTITUTE(UPPER(IFERROR(INDEX('Registro de Comisión'!$D$5:$D$304,MATCH(ROW()-21,'Registro de Comisión'!$P$5:$P$304,0)),"")),"Á","A"),"É","E"),"Í","I"),"Ó","O"),"Ú","U"),"Ü","U"))) | F23: =IF($B23="","",TRIM(SUBSTITUTE(SUBSTITUTE(SUBSTITUTE(SUBSTITUTE(SUBSTITUTE(SUBSTITUTE(UPPER(IFERROR(INDEX('Registro de Comisión'!$E$5:$E$304,MATCH(ROW()-21,'Registro de Comisión'!$P$5:$P$304,0)),"")),"Á","A"),"É","E"),"Í","I"),"Ó","O"),"Ú","U"),"Ü","U"))) | G23: =IF($B23="","",TRIM(SUBSTITUTE(SUBSTITUTE(SUBSTITUTE(SUBSTITUTE(SUBSTITUTE(SUBSTITUTE(UPPER(IFERROR(INDEX('Registro de Comisión'!$F$5:$F$304,MATCH(ROW()-21,'Registro de Comisión'!$P$5:$P$304,0)),"")),"Á","A"),"É","E"),"Í","I"),"Ó","O"),"Ú","U"),"Ü","U"))) | H23: =IF($B23="","",TRIM(SUBSTITUTE(SUBSTITUTE(SUBSTITUTE(SUBSTITUTE(SUBSTITUTE(SUBSTITUTE(UPPER(IFERROR(INDEX('Registro de Comisión'!$G$5:$G$304,MATCH(ROW()-21,'Registro de Comisión'!$P$5:$P$304,0)),"")),"Á","A"),"É","E"),"Í","I"),"Ó","O"),"Ú","U"),"Ü","U"))) | I23: =IF($B23="","",IFERROR(INDEX('Registro de Comisión'!$H$5:$H$304,MATCH(ROW()-21,'Registro de Comisión'!$P$5:$P$304,0)),"")) | J23: =IF($B23="","",TRIM(SUBSTITUTE(SUBSTITUTE(SUBSTITUTE(SUBSTITUTE(SUBSTITUTE(SUBSTITUTE(UPPER(IFERROR(INDEX(tblPeriodos[Institución en el Período],MATCH($B23&"-1",tblPeriodos[Clave (uso interno)],0)),"SIN PERIODO REGISTRADO")),"Á","A"),"É","E"),"Í","I"),"Ó","O"),"Ú","U"),"Ü","U"))) | K23: =IF($B23="","",IFERROR(_xlfn.MINIFS(tblPeriodos[Fecha Inicio del Período],tblPeriodos[Cédula],$B23),"")) | L23: =IF($B23="","",IFERROR(_xlfn.MAXIFS(tblPeriodos[Fecha Fin del Período],tblPeriodos[Cédula],$B23),"")) | M23: =IF($B23="","",COUNTIFS(tblPeriodos[Cédula],$B23)) | N23: =IF($B23="","",SUMIFS(tblPeriodos[Días del Período],tblPeriodos[Cédula],$B23)) | O23: =IF($B23="","",ROUND(N23/365.25,1)) | P23: =IF($B23="","",EDATE(K23,72)) | Q23: =IF($B23="","",P23-TODAY()) | R23: =IF($B23="","",IF(Q23<=0,"🔴 SUPERO LIMITE LEGAL",IF(Q23<=180,"🟠 PROXIMO AL LIMITE (6 ANOS)",IF(Q23<=365,"🟡 VIGILAR (< 1 ANO)","🟢 DENTRO DEL LIMITE")))) | S23: =IF($B23="","",L23-TODAY()) | T23: =IF($B23="","",IF(S23<0,"🔴 COMISION VENCIDA",IF(S23<=90,"🟠 VENCE PRONTO (<=90 DIAS)",IF(S23<=180,"🟡 PROXIMA A VENCER (<=180 DIAS)","🟢 VIGENTE")))) | U23: =IF($B23="","",IF(ABS(N23-(L23-K23+1))<=3,"CONTINUA","CON INTERRUPCIONES - REVISAR")) | V23: =IF($B23="","",TRIM(SUBSTITUTE(SUBSTITUTE(SUBSTITUTE(SUBSTITUTE(SUBSTITUTE(SUBSTITUTE(UPPER(IFERROR(INDEX('Registro de Comisión'!$L$5:$L$304,MATCH($B23&"-ACT",'Registro de Comisión'!$N$5:$N$304,0)),"SIN REGISTRAR")),"Á","A"),"É","E"),"Í","I"),"Ó","O"),"Ú","U"),"Ü","U")))
A24: =IF($B24="","",ROW()-6) | B24: =IFERROR(INDEX('Registro de Comisión'!$A$5:$A$304,MATCH(ROW()-21,'Registro de Comisión'!$P$5:$P$304,0)),"") | C24: =IF($B24="","",TRIM(SUBSTITUTE(SUBSTITUTE(SUBSTITUTE(SUBSTITUTE(SUBSTITUTE(SUBSTITUTE(UPPER(IFERROR(INDEX('Registro de Comisión'!$B$5:$B$304,MATCH(ROW()-21,'Registro de Comisión'!$P$5:$P$304,0)),"")),"Á","A"),"É","E"),"Í","I"),"Ó","O"),"Ú","U"),"Ü","U"))) | D24: =IF($B24="","",TRIM(SUBSTITUTE(SUBSTITUTE(SUBSTITUTE(SUBSTITUTE(SUBSTITUTE(SUBSTITUTE(UPPER(IFERROR(INDEX('Registro de Comisión'!$C$5:$C$304,MATCH(ROW()-21,'Registro de Comisión'!$P$5:$P$304,0)),"")),"Á","A"),"É","E"),"Í","I"),"Ó","O"),"Ú","U"),"Ü","U"))) | E24: =IF($B24="","",TRIM(SUBSTITUTE(SUBSTITUTE(SUBSTITUTE(SUBSTITUTE(SUBSTITUTE(SUBSTITUTE(UPPER(IFERROR(INDEX('Registro de Comisión'!$D$5:$D$304,MATCH(ROW()-21,'Registro de Comisión'!$P$5:$P$304,0)),"")),"Á","A"),"É","E"),"Í","I"),"Ó","O"),"Ú","U"),"Ü","U"))) | F24: =IF($B24="","",TRIM(SUBSTITUTE(SUBSTITUTE(SUBSTITUTE(SUBSTITUTE(SUBSTITUTE(SUBSTITUTE(UPPER(IFERROR(INDEX('Registro de Comisión'!$E$5:$E$304,MATCH(ROW()-21,'Registro de Comisión'!$P$5:$P$304,0)),"")),"Á","A"),"É","E"),"Í","I"),"Ó","O"),"Ú","U"),"Ü","U"))) | G24: =IF($B24="","",TRIM(SUBSTITUTE(SUBSTITUTE(SUBSTITUTE(SUBSTITUTE(SUBSTITUTE(SUBSTITUTE(UPPER(IFERROR(INDEX('Registro de Comisión'!$F$5:$F$304,MATCH(ROW()-21,'Registro de Comisión'!$P$5:$P$304,0)),"")),"Á","A"),"É","E"),"Í","I"),"Ó","O"),"Ú","U"),"Ü","U"))) | H24: =IF($B24="","",TRIM(SUBSTITUTE(SUBSTITUTE(SUBSTITUTE(SUBSTITUTE(SUBSTITUTE(SUBSTITUTE(UPPER(IFERROR(INDEX('Registro de Comisión'!$G$5:$G$304,MATCH(ROW()-21,'Registro de Comisión'!$P$5:$P$304,0)),"")),"Á","A"),"É","E"),"Í","I"),"Ó","O"),"Ú","U"),"Ü","U"))) | I24: =IF($B24="","",IFERROR(INDEX('Registro de Comisión'!$H$5:$H$304,MATCH(ROW()-21,'Registro de Comisión'!$P$5:$P$304,0)),"")) | J24: =IF($B24="","",TRIM(SUBSTITUTE(SUBSTITUTE(SUBSTITUTE(SUBSTITUTE(SUBSTITUTE(SUBSTITUTE(UPPER(IFERROR(INDEX(tblPeriodos[Institución en el Período],MATCH($B24&"-1",tblPeriodos[Clave (uso interno)],0)),"SIN PERIODO REGISTRADO")),"Á","A"),"É","E"),"Í","I"),"Ó","O"),"Ú","U"),"Ü","U"))) | K24: =IF($B24="","",IFERROR(_xlfn.MINIFS(tblPeriodos[Fecha Inicio del Período],tblPeriodos[Cédula],$B24),"")) | L24: =IF($B24="","",IFERROR(_xlfn.MAXIFS(tblPeriodos[Fecha Fin del Período],tblPeriodos[Cédula],$B24),"")) | M24: =IF($B24="","",COUNTIFS(tblPeriodos[Cédula],$B24)) | N24: =IF($B24="","",SUMIFS(tblPeriodos[Días del Período],tblPeriodos[Cédula],$B24)) | O24: =IF($B24="","",ROUND(N24/365.25,1)) | P24: =IF($B24="","",EDATE(K24,72)) | Q24: =IF($B24="","",P24-TODAY()) | R24: =IF($B24="","",IF(Q24<=0,"🔴 SUPERO LIMITE LEGAL",IF(Q24<=180,"🟠 PROXIMO AL LIMITE (6 ANOS)",IF(Q24<=365,"🟡 VIGILAR (< 1 ANO)","🟢 DENTRO DEL LIMITE")))) | S24: =IF($B24="","",L24-TODAY()) | T24: =IF($B24="","",IF(S24<0,"🔴 COMISION VENCIDA",IF(S24<=90,"🟠 VENCE PRONTO (<=90 DIAS)",IF(S24<=180,"🟡 PROXIMA A VENCER (<=180 DIAS)","🟢 VIGENTE")))) | U24: =IF($B24="","",IF(ABS(N24-(L24-K24+1))<=3,"CONTINUA","CON INTERRUPCIONES - REVISAR")) | V24: =IF($B24="","",TRIM(SUBSTITUTE(SUBSTITUTE(SUBSTITUTE(SUBSTITUTE(SUBSTITUTE(SUBSTITUTE(UPPER(IFERROR(INDEX('Registro de Comisión'!$L$5:$L$304,MATCH($B24&"-ACT",'Registro de Comisión'!$N$5:$N$304,0)),"SIN REGISTRAR")),"Á","A"),"É","E"),"Í","I"),"Ó","O"),"Ú","U"),"Ü","U")))
A25: =IF($B25="","",ROW()-6) | B25: =IFERROR(INDEX('Registro de Comisión'!$A$5:$A$304,MATCH(ROW()-21,'Registro de Comisión'!$P$5:$P$304,0)),"") | C25: =IF($B25="","",TRIM(SUBSTITUTE(SUBSTITUTE(SUBSTITUTE(SUBSTITUTE(SUBSTITUTE(SUBSTITUTE(UPPER(IFERROR(INDEX('Registro de Comisión'!$B$5:$B$304,MATCH(ROW()-21,'Registro de Comisión'!$P$5:$P$304,0)),"")),"Á","A"),"É","E"),"Í","I"),"Ó","O"),"Ú","U"),"Ü","U"))) | D25: =IF($B25="","",TRIM(SUBSTITUTE(SUBSTITUTE(SUBSTITUTE(SUBSTITUTE(SUBSTITUTE(SUBSTITUTE(UPPER(IFERROR(INDEX('Registro de Comisión'!$C$5:$C$304,MATCH(ROW()-21,'Registro de Comisión'!$P$5:$P$304,0)),"")),"Á","A"),"É","E"),"Í","I"),"Ó","O"),"Ú","U"),"Ü","U"))) | E25: =IF($B25="","",TRIM(SUBSTITUTE(SUBSTITUTE(SUBSTITUTE(SUBSTITUTE(SUBSTITUTE(SUBSTITUTE(UPPER(IFERROR(INDEX('Registro de Comisión'!$D$5:$D$304,MATCH(ROW()-21,'Registro de Comisión'!$P$5:$P$304,0)),"")),"Á","A"),"É","E"),"Í","I"),"Ó","O"),"Ú","U"),"Ü","U"))) | F25: =IF($B25="","",TRIM(SUBSTITUTE(SUBSTITUTE(SUBSTITUTE(SUBSTITUTE(SUBSTITUTE(SUBSTITUTE(UPPER(IFERROR(INDEX('Registro de Comisión'!$E$5:$E$304,MATCH(ROW()-21,'Registro de Comisión'!$P$5:$P$304,0)),"")),"Á","A"),"É","E"),"Í","I"),"Ó","O"),"Ú","U"),"Ü","U"))) | G25: =IF($B25="","",TRIM(SUBSTITUTE(SUBSTITUTE(SUBSTITUTE(SUBSTITUTE(SUBSTITUTE(SUBSTITUTE(UPPER(IFERROR(INDEX('Registro de Comisión'!$F$5:$F$304,MATCH(ROW()-21,'Registro de Comisión'!$P$5:$P$304,0)),"")),"Á","A"),"É","E"),"Í","I"),"Ó","O"),"Ú","U"),"Ü","U"))) | H25: =IF($B25="","",TRIM(SUBSTITUTE(SUBSTITUTE(SUBSTITUTE(SUBSTITUTE(SUBSTITUTE(SUBSTITUTE(UPPER(IFERROR(INDEX('Registro de Comisión'!$G$5:$G$304,MATCH(ROW()-21,'Registro de Comisión'!$P$5:$P$304,0)),"")),"Á","A"),"É","E"),"Í","I"),"Ó","O"),"Ú","U"),"Ü","U"))) | I25: =IF($B25="","",IFERROR(INDEX('Registro de Comisión'!$H$5:$H$304,MATCH(ROW()-21,'Registro de Comisión'!$P$5:$P$304,0)),"")) | J25: =IF($B25="","",TRIM(SUBSTITUTE(SUBSTITUTE(SUBSTITUTE(SUBSTITUTE(SUBSTITUTE(SUBSTITUTE(UPPER(IFERROR(INDEX(tblPeriodos[Institución en el Período],MATCH($B25&"-1",tblPeriodos[Clave (uso interno)],0)),"SIN PERIODO REGISTRADO")),"Á","A"),"É","E"),"Í","I"),"Ó","O"),"Ú","U"),"Ü","U"))) | K25: =IF($B25="","",IFERROR(_xlfn.MINIFS(tblPeriodos[Fecha Inicio del Período],tblPeriodos[Cédula],$B25),"")) | L25: =IF($B25="","",IFERROR(_xlfn.MAXIFS(tblPeriodos[Fecha Fin del Período],tblPeriodos[Cédula],$B25),"")) | M25: =IF($B25="","",COUNTIFS(tblPeriodos[Cédula],$B25)) | N25: =IF($B25="","",SUMIFS(tblPeriodos[Días del Período],tblPeriodos[Cédula],$B25)) | O25: =IF($B25="","",ROUND(N25/365.25,1)) | P25: =IF($B25="","",EDATE(K25,72)) | Q25: =IF($B25="","",P25-TODAY()) | R25: =IF($B25="","",IF(Q25<=0,"🔴 SUPERO LIMITE LEGAL",IF(Q25<=180,"🟠 PROXIMO AL LIMITE (6 ANOS)",IF(Q25<=365,"🟡 VIGILAR (< 1 ANO)","🟢 DENTRO DEL LIMITE")))) | S25: =IF($B25="","",L25-TODAY()) | T25: =IF($B25="","",IF(S25<0,"🔴 COMISION VENCIDA",IF(S25<=90,"🟠 VENCE PRONTO (<=90 DIAS)",IF(S25<=180,"🟡 PROXIMA A VENCER (<=180 DIAS)","🟢 VIGENTE")))) | U25: =IF($B25="","",IF(ABS(N25-(L25-K25+1))<=3,"CONTINUA","CON INTERRUPCIONES - REVISAR")) | V25: =IF($B25="","",TRIM(SUBSTITUTE(SUBSTITUTE(SUBSTITUTE(SUBSTITUTE(SUBSTITUTE(SUBSTITUTE(UPPER(IFERROR(INDEX('Registro de Comisión'!$L$5:$L$304,MATCH($B25&"-ACT",'Registro de Comisión'!$N$5:$N$304,0)),"SIN REGISTRAR")),"Á","A"),"É","E"),"Í","I"),"Ó","O"),"Ú","U"),"Ü","U")))
A26: =IF($B26="","",ROW()-6) | B26: =IFERROR(INDEX('Registro de Comisión'!$A$5:$A$304,MATCH(ROW()-21,'Registro de Comisión'!$P$5:$P$304,0)),"") | C26: =IF($B26="","",TRIM(SUBSTITUTE(SUBSTITUTE(SUBSTITUTE(SUBSTITUTE(SUBSTITUTE(SUBSTITUTE(UPPER(IFERROR(INDEX('Registro de Comisión'!$B$5:$B$304,MATCH(ROW()-21,'Registro de Comisión'!$P$5:$P$304,0)),"")),"Á","A"),"É","E"),"Í","I"),"Ó","O"),"Ú","U"),"Ü","U"))) | D26: =IF($B26="","",TRIM(SUBSTITUTE(SUBSTITUTE(SUBSTITUTE(SUBSTITUTE(SUBSTITUTE(SUBSTITUTE(UPPER(IFERROR(INDEX('Registro de Comisión'!$C$5:$C$304,MATCH(ROW()-21,'Registro de Comisión'!$P$5:$P$304,0)),"")),"Á","A"),"É","E"),"Í","I"),"Ó","O"),"Ú","U"),"Ü","U"))) | E26: =IF($B26="","",TRIM(SUBSTITUTE(SUBSTITUTE(SUBSTITUTE(SUBSTITUTE(SUBSTITUTE(SUBSTITUTE(UPPER(IFERROR(INDEX('Registro de Comisión'!$D$5:$D$304,MATCH(ROW()-21,'Registro de Comisión'!$P$5:$P$304,0)),"")),"Á","A"),"É","E"),"Í","I"),"Ó","O"),"Ú","U"),"Ü","U"))) | F26: =IF($B26="","",TRIM(SUBSTITUTE(SUBSTITUTE(SUBSTITUTE(SUBSTITUTE(SUBSTITUTE(SUBSTITUTE(UPPER(IFERROR(INDEX('Registro de Comisión'!$E$5:$E$304,MATCH(ROW()-21,'Registro de Comisión'!$P$5:$P$304,0)),"")),"Á","A"),"É","E"),"Í","I"),"Ó","O"),"Ú","U"),"Ü","U"))) | G26: =IF($B26="","",TRIM(SUBSTITUTE(SUBSTITUTE(SUBSTITUTE(SUBSTITUTE(SUBSTITUTE(SUBSTITUTE(UPPER(IFERROR(INDEX('Registro de Comisión'!$F$5:$F$304,MATCH(ROW()-21,'Registro de Comisión'!$P$5:$P$304,0)),"")),"Á","A"),"É","E"),"Í","I"),"Ó","O"),"Ú","U"),"Ü","U"))) | H26: =IF($B26="","",TRIM(SUBSTITUTE(SUBSTITUTE(SUBSTITUTE(SUBSTITUTE(SUBSTITUTE(SUBSTITUTE(UPPER(IFERROR(INDEX('Registro de Comisión'!$G$5:$G$304,MATCH(ROW()-21,'Registro de Comisión'!$P$5:$P$304,0)),"")),"Á","A"),"É","E"),"Í","I"),"Ó","O"),"Ú","U"),"Ü","U"))) | I26: =IF($B26="","",IFERROR(INDEX('Registro de Comisión'!$H$5:$H$304,MATCH(ROW()-21,'Registro de Comisión'!$P$5:$P$304,0)),"")) | J26: =IF($B26="","",TRIM(SUBSTITUTE(SUBSTITUTE(SUBSTITUTE(SUBSTITUTE(SUBSTITUTE(SUBSTITUTE(UPPER(IFERROR(INDEX(tblPeriodos[Institución en el Período],MATCH($B26&"-1",tblPeriodos[Clave (uso interno)],0)),"SIN PERIODO REGISTRADO")),"Á","A"),"É","E"),"Í","I"),"Ó","O"),"Ú","U"),"Ü","U"))) | K26: =IF($B26="","",IFERROR(_xlfn.MINIFS(tblPeriodos[Fecha Inicio del Período],tblPeriodos[Cédula],$B26),"")) | L26: =IF($B26="","",IFERROR(_xlfn.MAXIFS(tblPeriodos[Fecha Fin del Período],tblPeriodos[Cédula],$B26),"")) | M26: =IF($B26="","",COUNTIFS(tblPeriodos[Cédula],$B26)) | N26: =IF($B26="","",SUMIFS(tblPeriodos[Días del Período],tblPeriodos[Cédula],$B26)) | O26: =IF($B26="","",ROUND(N26/365.25,1)) | P26: =IF($B26="","",EDATE(K26,72)) | Q26: =IF($B26="","",P26-TODAY()) | R26: =IF($B26="","",IF(Q26<=0,"🔴 SUPERO LIMITE LEGAL",IF(Q26<=180,"🟠 PROXIMO AL LIMITE (6 ANOS)",IF(Q26<=365,"🟡 VIGILAR (< 1 ANO)","🟢 DENTRO DEL LIMITE")))) | S26: =IF($B26="","",L26-TODAY()) | T26: =IF($B26="","",IF(S26<0,"🔴 COMISION VENCIDA",IF(S26<=90,"🟠 VENCE PRONTO (<=90 DIAS)",IF(S26<=180,"🟡 PROXIMA A VENCER (<=180 DIAS)","🟢 VIGENTE")))) | U26: =IF($B26="","",IF(ABS(N26-(L26-K26+1))<=3,"CONTINUA","CON INTERRUPCIONES - REVISAR")) | V26: =IF($B26="","",TRIM(SUBSTITUTE(SUBSTITUTE(SUBSTITUTE(SUBSTITUTE(SUBSTITUTE(SUBSTITUTE(UPPER(IFERROR(INDEX('Registro de Comisión'!$L$5:$L$304,MATCH($B26&"-ACT",'Registro de Comisión'!$N$5:$N$304,0)),"SIN REGISTRAR")),"Á","A"),"É","E"),"Í","I"),"Ó","O"),"Ú","U"),"Ü","U")))
A27: =IF($B27="","",ROW()-6) | B27: =IFERROR(INDEX('Registro de Comisión'!$A$5:$A$304,MATCH(ROW()-21,'Registro de Comisión'!$P$5:$P$304,0)),"") | C27: =IF($B27="","",TRIM(SUBSTITUTE(SUBSTITUTE(SUBSTITUTE(SUBSTITUTE(SUBSTITUTE(SUBSTITUTE(UPPER(IFERROR(INDEX('Registro de Comisión'!$B$5:$B$304,MATCH(ROW()-21,'Registro de Comisión'!$P$5:$P$304,0)),"")),"Á","A"),"É","E"),"Í","I"),"Ó","O"),"Ú","U"),"Ü","U"))) | D27: =IF($B27="","",TRIM(SUBSTITUTE(SUBSTITUTE(SUBSTITUTE(SUBSTITUTE(SUBSTITUTE(SUBSTITUTE(UPPER(IFERROR(INDEX('Registro de Comisión'!$C$5:$C$304,MATCH(ROW()-21,'Registro de Comisión'!$P$5:$P$304,0)),"")),"Á","A"),"É","E"),"Í","I"),"Ó","O"),"Ú","U"),"Ü","U"))) | E27: =IF($B27="","",TRIM(SUBSTITUTE(SUBSTITUTE(SUBSTITUTE(SUBSTITUTE(SUBSTITUTE(SUBSTITUTE(UPPER(IFERROR(INDEX('Registro de Comisión'!$D$5:$D$304,MATCH(ROW()-21,'Registro de Comisión'!$P$5:$P$304,0)),"")),"Á","A"),"É","E"),"Í","I"),"Ó","O"),"Ú","U"),"Ü","U"))) | F27: =IF($B27="","",TRIM(SUBSTITUTE(SUBSTITUTE(SUBSTITUTE(SUBSTITUTE(SUBSTITUTE(SUBSTITUTE(UPPER(IFERROR(INDEX('Registro de Comisión'!$E$5:$E$304,MATCH(ROW()-21,'Registro de Comisión'!$P$5:$P$304,0)),"")),"Á","A"),"É","E"),"Í","I"),"Ó","O"),"Ú","U"),"Ü","U"))) | G27: =IF($B27="","",TRIM(SUBSTITUTE(SUBSTITUTE(SUBSTITUTE(SUBSTITUTE(SUBSTITUTE(SUBSTITUTE(UPPER(IFERROR(INDEX('Registro de Comisión'!$F$5:$F$304,MATCH(ROW()-21,'Registro de Comisión'!$P$5:$P$304,0)),"")),"Á","A"),"É","E"),"Í","I"),"Ó","O"),"Ú","U"),"Ü","U"))) | H27: =IF($B27="","",TRIM(SUBSTITUTE(SUBSTITUTE(SUBSTITUTE(SUBSTITUTE(SUBSTITUTE(SUBSTITUTE(UPPER(IFERROR(INDEX('Registro de Comisión'!$G$5:$G$304,MATCH(ROW()-21,'Registro de Comisión'!$P$5:$P$304,0)),"")),"Á","A"),"É","E"),"Í","I"),"Ó","O"),"Ú","U"),"Ü","U"))) | I27: =IF($B27="","",IFERROR(INDEX('Registro de Comisión'!$H$5:$H$304,MATCH(ROW()-21,'Registro de Comisión'!$P$5:$P$304,0)),"")) | J27: =IF($B27="","",TRIM(SUBSTITUTE(SUBSTITUTE(SUBSTITUTE(SUBSTITUTE(SUBSTITUTE(SUBSTITUTE(UPPER(IFERROR(INDEX(tblPeriodos[Institución en el Período],MATCH($B27&"-1",tblPeriodos[Clave (uso interno)],0)),"SIN PERIODO REGISTRADO")),"Á","A"),"É","E"),"Í","I"),"Ó","O"),"Ú","U"),"Ü","U"))) | K27: =IF($B27="","",IFERROR(_xlfn.MINIFS(tblPeriodos[Fecha Inicio del Período],tblPeriodos[Cédula],$B27),"")) | L27: =IF($B27="","",IFERROR(_xlfn.MAXIFS(tblPeriodos[Fecha Fin del Período],tblPeriodos[Cédula],$B27),"")) | M27: =IF($B27="","",COUNTIFS(tblPeriodos[Cédula],$B27)) | N27: =IF($B27="","",SUMIFS(tblPeriodos[Días del Período],tblPeriodos[Cédula],$B27)) | O27: =IF($B27="","",ROUND(N27/365.25,1)) | P27: =IF($B27="","",EDATE(K27,72)) | Q27: =IF($B27="","",P27-TODAY()) | R27: =IF($B27="","",IF(Q27<=0,"🔴 SUPERO LIMITE LEGAL",IF(Q27<=180,"🟠 PROXIMO AL LIMITE (6 ANOS)",IF(Q27<=365,"🟡 VIGILAR (< 1 ANO)","🟢 DENTRO DEL LIMITE")))) | S27: =IF($B27="","",L27-TODAY()) | T27: =IF($B27="","",IF(S27<0,"🔴 COMISION VENCIDA",IF(S27<=90,"🟠 VENCE PRONTO (<=90 DIAS)",IF(S27<=180,"🟡 PROXIMA A VENCER (<=180 DIAS)","🟢 VIGENTE")))) | U27: =IF($B27="","",IF(ABS(N27-(L27-K27+1))<=3,"CONTINUA","CON INTERRUPCIONES - REVISAR")) | V27: =IF($B27="","",TRIM(SUBSTITUTE(SUBSTITUTE(SUBSTITUTE(SUBSTITUTE(SUBSTITUTE(SUBSTITUTE(UPPER(IFERROR(INDEX('Registro de Comisión'!$L$5:$L$304,MATCH($B27&"-ACT",'Registro de Comisión'!$N$5:$N$304,0)),"SIN REGISTRAR")),"Á","A"),"É","E"),"Í","I"),"Ó","O"),"Ú","U"),"Ü","U")))
A28: =IF($B28="","",ROW()-6) | B28: =IFERROR(INDEX('Registro de Comisión'!$A$5:$A$304,MATCH(ROW()-21,'Registro de Comisión'!$P$5:$P$304,0)),"") | C28: =IF($B28="","",TRIM(SUBSTITUTE(SUBSTITUTE(SUBSTITUTE(SUBSTITUTE(SUBSTITUTE(SUBSTITUTE(UPPER(IFERROR(INDEX('Registro de Comisión'!$B$5:$B$304,MATCH(ROW()-21,'Registro de Comisión'!$P$5:$P$304,0)),"")),"Á","A"),"É","E"),"Í","I"),"Ó","O"),"Ú","U"),"Ü","U"))) | D28: =IF($B28="","",TRIM(SUBSTITUTE(SUBSTITUTE(SUBSTITUTE(SUBSTITUTE(SUBSTITUTE(SUBSTITUTE(UPPER(IFERROR(INDEX('Registro de Comisión'!$C$5:$C$304,MATCH(ROW()-21,'Registro de Comisión'!$P$5:$P$304,0)),"")),"Á","A"),"É","E"),"Í","I"),"Ó","O"),"Ú","U"),"Ü","U"))) | E28: =IF($B28="","",TRIM(SUBSTITUTE(SUBSTITUTE(SUBSTITUTE(SUBSTITUTE(SUBSTITUTE(SUBSTITUTE(UPPER(IFERROR(INDEX('Registro de Comisión'!$D$5:$D$304,MATCH(ROW()-21,'Registro de Comisión'!$P$5:$P$304,0)),"")),"Á","A"),"É","E"),"Í","I"),"Ó","O"),"Ú","U"),"Ü","U"))) | F28: =IF($B28="","",TRIM(SUBSTITUTE(SUBSTITUTE(SUBSTITUTE(SUBSTITUTE(SUBSTITUTE(SUBSTITUTE(UPPER(IFERROR(INDEX('Registro de Comisión'!$E$5:$E$304,MATCH(ROW()-21,'Registro de Comisión'!$P$5:$P$304,0)),"")),"Á","A"),"É","E"),"Í","I"),"Ó","O"),"Ú","U"),"Ü","U"))) | G28: =IF($B28="","",TRIM(SUBSTITUTE(SUBSTITUTE(SUBSTITUTE(SUBSTITUTE(SUBSTITUTE(SUBSTITUTE(UPPER(IFERROR(INDEX('Registro de Comisión'!$F$5:$F$304,MATCH(ROW()-21,'Registro de Comisión'!$P$5:$P$304,0)),"")),"Á","A"),"É","E"),"Í","I"),"Ó","O"),"Ú","U"),"Ü","U"))) | H28: =IF($B28="","",TRIM(SUBSTITUTE(SUBSTITUTE(SUBSTITUTE(SUBSTITUTE(SUBSTITUTE(SUBSTITUTE(UPPER(IFERROR(INDEX('Registro de Comisión'!$G$5:$G$304,MATCH(ROW()-21,'Registro de Comisión'!$P$5:$P$304,0)),"")),"Á","A"),"É","E"),"Í","I"),"Ó","O"),"Ú","U"),"Ü","U"))) | I28: =IF($B28="","",IFERROR(INDEX('Registro de Comisión'!$H$5:$H$304,MATCH(ROW()-21,'Registro de Comisión'!$P$5:$P$304,0)),"")) | J28: =IF($B28="","",TRIM(SUBSTITUTE(SUBSTITUTE(SUBSTITUTE(SUBSTITUTE(SUBSTITUTE(SUBSTITUTE(UPPER(IFERROR(INDEX(tblPeriodos[Institución en el Período],MATCH($B28&"-1",tblPeriodos[Clave (uso interno)],0)),"SIN PERIODO REGISTRADO")),"Á","A"),"É","E"),"Í","I"),"Ó","O"),"Ú","U"),"Ü","U"))) | K28: =IF($B28="","",IFERROR(_xlfn.MINIFS(tblPeriodos[Fecha Inicio del Período],tblPeriodos[Cédula],$B28),"")) | L28: =IF($B28="","",IFERROR(_xlfn.MAXIFS(tblPeriodos[Fecha Fin del Período],tblPeriodos[Cédula],$B28),"")) | M28: =IF($B28="","",COUNTIFS(tblPeriodos[Cédula],$B28)) | N28: =IF($B28="","",SUMIFS(tblPeriodos[Días del Período],tblPeriodos[Cédula],$B28)) | O28: =IF($B28="","",ROUND(N28/365.25,1)) | P28: =IF($B28="","",EDATE(K28,72)) | Q28: =IF($B28="","",P28-TODAY()) | R28: =IF($B28="","",IF(Q28<=0,"🔴 SUPERO LIMITE LEGAL",IF(Q28<=180,"🟠 PROXIMO AL LIMITE (6 ANOS)",IF(Q28<=365,"🟡 VIGILAR (< 1 ANO)","🟢 DENTRO DEL LIMITE")))) | S28: =IF($B28="","",L28-TODAY()) | T28: =IF($B28="","",IF(S28<0,"🔴 COMISION VENCIDA",IF(S28<=90,"🟠 VENCE PRONTO (<=90 DIAS)",IF(S28<=180,"🟡 PROXIMA A VENCER (<=180 DIAS)","🟢 VIGENTE")))) | U28: =IF($B28="","",IF(ABS(N28-(L28-K28+1))<=3,"CONTINUA","CON INTERRUPCIONES - REVISAR")) | V28: =IF($B28="","",TRIM(SUBSTITUTE(SUBSTITUTE(SUBSTITUTE(SUBSTITUTE(SUBSTITUTE(SUBSTITUTE(UPPER(IFERROR(INDEX('Registro de Comisión'!$L$5:$L$304,MATCH($B28&"-ACT",'Registro de Comisión'!$N$5:$N$304,0)),"SIN REGISTRAR")),"Á","A"),"É","E"),"Í","I"),"Ó","O"),"Ú","U"),"Ü","U")))
A29: =IF($B29="","",ROW()-6) | B29: =IFERROR(INDEX('Registro de Comisión'!$A$5:$A$304,MATCH(ROW()-21,'Registro de Comisión'!$P$5:$P$304,0)),"") | C29: =IF($B29="","",TRIM(SUBSTITUTE(SUBSTITUTE(SUBSTITUTE(SUBSTITUTE(SUBSTITUTE(SUBSTITUTE(UPPER(IFERROR(INDEX('Registro de Comisión'!$B$5:$B$304,MATCH(ROW()-21,'Registro de Comisión'!$P$5:$P$304,0)),"")),"Á","A"),"É","E"),"Í","I"),"Ó","O"),"Ú","U"),"Ü","U"))) | D29: =IF($B29="","",TRIM(SUBSTITUTE(SUBSTITUTE(SUBSTITUTE(SUBSTITUTE(SUBSTITUTE(SUBSTITUTE(UPPER(IFERROR(INDEX('Registro de Comisión'!$C$5:$C$304,MATCH(ROW()-21,'Registro de Comisión'!$P$5:$P$304,0)),"")),"Á","A"),"É","E"),"Í","I"),"Ó","O"),"Ú","U"),"Ü","U"))) | E29: =IF($B29="","",TRIM(SUBSTITUTE(SUBSTITUTE(SUBSTITUTE(SUBSTITUTE(SUBSTITUTE(SUBSTITUTE(UPPER(IFERROR(INDEX('Registro de Comisión'!$D$5:$D$304,MATCH(ROW()-21,'Registro de Comisión'!$P$5:$P$304,0)),"")),"Á","A"),"É","E"),"Í","I"),"Ó","O"),"Ú","U"),"Ü","U"))) | F29: =IF($B29="","",TRIM(SUBSTITUTE(SUBSTITUTE(SUBSTITUTE(SUBSTITUTE(SUBSTITUTE(SUBSTITUTE(UPPER(IFERROR(INDEX('Registro de Comisión'!$E$5:$E$304,MATCH(ROW()-21,'Registro de Comisión'!$P$5:$P$304,0)),"")),"Á","A"),"É","E"),"Í","I"),"Ó","O"),"Ú","U"),"Ü","U"))) | G29: =IF($B29="","",TRIM(SUBSTITUTE(SUBSTITUTE(SUBSTITUTE(SUBSTITUTE(SUBSTITUTE(SUBSTITUTE(UPPER(IFERROR(INDEX('Registro de Comisión'!$F$5:$F$304,MATCH(ROW()-21,'Registro de Comisión'!$P$5:$P$304,0)),"")),"Á","A"),"É","E"),"Í","I"),"Ó","O"),"Ú","U"),"Ü","U"))) | H29: =IF($B29="","",TRIM(SUBSTITUTE(SUBSTITUTE(SUBSTITUTE(SUBSTITUTE(SUBSTITUTE(SUBSTITUTE(UPPER(IFERROR(INDEX('Registro de Comisión'!$G$5:$G$304,MATCH(ROW()-21,'Registro de Comisión'!$P$5:$P$304,0)),"")),"Á","A"),"É","E"),"Í","I"),"Ó","O"),"Ú","U"),"Ü","U"))) | I29: =IF($B29="","",IFERROR(INDEX('Registro de Comisión'!$H$5:$H$304,MATCH(ROW()-21,'Registro de Comisión'!$P$5:$P$304,0)),"")) | J29: =IF($B29="","",TRIM(SUBSTITUTE(SUBSTITUTE(SUBSTITUTE(SUBSTITUTE(SUBSTITUTE(SUBSTITUTE(UPPER(IFERROR(INDEX(tblPeriodos[Institución en el Período],MATCH($B29&"-1",tblPeriodos[Clave (uso interno)],0)),"SIN PERIODO REGISTRADO")),"Á","A"),"É","E"),"Í","I"),"Ó","O"),"Ú","U"),"Ü","U"))) | K29: =IF($B29="","",IFERROR(_xlfn.MINIFS(tblPeriodos[Fecha Inicio del Período],tblPeriodos[Cédula],$B29),"")) | L29: =IF($B29="","",IFERROR(_xlfn.MAXIFS(tblPeriodos[Fecha Fin del Período],tblPeriodos[Cédula],$B29),"")) | M29: =IF($B29="","",COUNTIFS(tblPeriodos[Cédula],$B29)) | N29: =IF($B29="","",SUMIFS(tblPeriodos[Días del Período],tblPeriodos[Cédula],$B29)) | O29: =IF($B29="","",ROUND(N29/365.25,1)) | P29: =IF($B29="","",EDATE(K29,72)) | Q29: =IF($B29="","",P29-TODAY()) | R29: =IF($B29="","",IF(Q29<=0,"🔴 SUPERO LIMITE LEGAL",IF(Q29<=180,"🟠 PROXIMO AL LIMITE (6 ANOS)",IF(Q29<=365,"🟡 VIGILAR (< 1 ANO)","🟢 DENTRO DEL LIMITE")))) | S29: =IF($B29="","",L29-TODAY()) | T29: =IF($B29="","",IF(S29<0,"🔴 COMISION VENCIDA",IF(S29<=90,"🟠 VENCE PRONTO (<=90 DIAS)",IF(S29<=180,"🟡 PROXIMA A VENCER (<=180 DIAS)","🟢 VIGENTE")))) | U29: =IF($B29="","",IF(ABS(N29-(L29-K29+1))<=3,"CONTINUA","CON INTERRUPCIONES - REVISAR")) | V29: =IF($B29="","",TRIM(SUBSTITUTE(SUBSTITUTE(SUBSTITUTE(SUBSTITUTE(SUBSTITUTE(SUBSTITUTE(UPPER(IFERROR(INDEX('Registro de Comisión'!$L$5:$L$304,MATCH($B29&"-ACT",'Registro de Comisión'!$N$5:$N$304,0)),"SIN REGISTRAR")),"Á","A"),"É","E"),"Í","I"),"Ó","O"),"Ú","U"),"Ü","U")))
A30: =IF($B30="","",ROW()-6) | B30: =IFERROR(INDEX('Registro de Comisión'!$A$5:$A$304,MATCH(ROW()-21,'Registro de Comisión'!$P$5:$P$304,0)),"") | C30: =IF($B30="","",TRIM(SUBSTITUTE(SUBSTITUTE(SUBSTITUTE(SUBSTITUTE(SUBSTITUTE(SUBSTITUTE(UPPER(IFERROR(INDEX('Registro de Comisión'!$B$5:$B$304,MATCH(ROW()-21,'Registro de Comisión'!$P$5:$P$304,0)),"")),"Á","A"),"É","E"),"Í","I"),"Ó","O"),"Ú","U"),"Ü","U"))) | D30: =IF($B30="","",TRIM(SUBSTITUTE(SUBSTITUTE(SUBSTITUTE(SUBSTITUTE(SUBSTITUTE(SUBSTITUTE(UPPER(IFERROR(INDEX('Registro de Comisión'!$C$5:$C$304,MATCH(ROW()-21,'Registro de Comisión'!$P$5:$P$304,0)),"")),"Á","A"),"É","E"),"Í","I"),"Ó","O"),"Ú","U"),"Ü","U"))) | E30: =IF($B30="","",TRIM(SUBSTITUTE(SUBSTITUTE(SUBSTITUTE(SUBSTITUTE(SUBSTITUTE(SUBSTITUTE(UPPER(IFERROR(INDEX('Registro de Comisión'!$D$5:$D$304,MATCH(ROW()-21,'Registro de Comisión'!$P$5:$P$304,0)),"")),"Á","A"),"É","E"),"Í","I"),"Ó","O"),"Ú","U"),"Ü","U"))) | F30: =IF($B30="","",TRIM(SUBSTITUTE(SUBSTITUTE(SUBSTITUTE(SUBSTITUTE(SUBSTITUTE(SUBSTITUTE(UPPER(IFERROR(INDEX('Registro de Comisión'!$E$5:$E$304,MATCH(ROW()-21,'Registro de Comisión'!$P$5:$P$304,0)),"")),"Á","A"),"É","E"),"Í","I"),"Ó","O"),"Ú","U"),"Ü","U"))) | G30: =IF($B30="","",TRIM(SUBSTITUTE(SUBSTITUTE(SUBSTITUTE(SUBSTITUTE(SUBSTITUTE(SUBSTITUTE(UPPER(IFERROR(INDEX('Registro de Comisión'!$F$5:$F$304,MATCH(ROW()-21,'Registro de Comisión'!$P$5:$P$304,0)),"")),"Á","A"),"É","E"),"Í","I"),"Ó","O"),"Ú","U"),"Ü","U"))) | H30: =IF($B30="","",TRIM(SUBSTITUTE(SUBSTITUTE(SUBSTITUTE(SUBSTITUTE(SUBSTITUTE(SUBSTITUTE(UPPER(IFERROR(INDEX('Registro de Comisión'!$G$5:$G$304,MATCH(ROW()-21,'Registro de Comisión'!$P$5:$P$304,0)),"")),"Á","A"),"É","E"),"Í","I"),"Ó","O"),"Ú","U"),"Ü","U"))) | I30: =IF($B30="","",IFERROR(INDEX('Registro de Comisión'!$H$5:$H$304,MATCH(ROW()-21,'Registro de Comisión'!$P$5:$P$304,0)),"")) | J30: =IF($B30="","",TRIM(SUBSTITUTE(SUBSTITUTE(SUBSTITUTE(SUBSTITUTE(SUBSTITUTE(SUBSTITUTE(UPPER(IFERROR(INDEX(tblPeriodos[Institución en el Período],MATCH($B30&"-1",tblPeriodos[Clave (uso interno)],0)),"SIN PERIODO REGISTRADO")),"Á","A"),"É","E"),"Í","I"),"Ó","O"),"Ú","U"),"Ü","U"))) | K30: =IF($B30="","",IFERROR(_xlfn.MINIFS(tblPeriodos[Fecha Inicio del Período],tblPeriodos[Cédula],$B30),"")) | L30: =IF($B30="","",IFERROR(_xlfn.MAXIFS(tblPeriodos[Fecha Fin del Período],tblPeriodos[Cédula],$B30),"")) | M30: =IF($B30="","",COUNTIFS(tblPeriodos[Cédula],$B30)) | N30: =IF($B30="","",SUMIFS(tblPeriodos[Días del Período],tblPeriodos[Cédula],$B30)) | O30: =IF($B30="","",ROUND(N30/365.25,1)) | P30: =IF($B30="","",EDATE(K30,72)) | Q30: =IF($B30="","",P30-TODAY()) | R30: =IF($B30="","",IF(Q30<=0,"🔴 SUPERO LIMITE LEGAL",IF(Q30<=180,"🟠 PROXIMO AL LIMITE (6 ANOS)",IF(Q30<=365,"🟡 VIGILAR (< 1 ANO)","🟢 DENTRO DEL LIMITE")))) | S30: =IF($B30="","",L30-TODAY()) | T30: =IF($B30="","",IF(S30<0,"🔴 COMISION VENCIDA",IF(S30<=90,"🟠 VENCE PRONTO (<=90 DIAS)",IF(S30<=180,"🟡 PROXIMA A VENCER (<=180 DIAS)","🟢 VIGENTE")))) | U30: =IF($B30="","",IF(ABS(N30-(L30-K30+1))<=3,"CONTINUA","CON INTERRUPCIONES - REVISAR")) | V30: =IF($B30="","",TRIM(SUBSTITUTE(SUBSTITUTE(SUBSTITUTE(SUBSTITUTE(SUBSTITUTE(SUBSTITUTE(UPPER(IFERROR(INDEX('Registro de Comisión'!$L$5:$L$304,MATCH($B30&"-ACT",'Registro de Comisión'!$N$5:$N$304,0)),"SIN REGISTRAR")),"Á","A"),"É","E"),"Í","I"),"Ó","O"),"Ú","U"),"Ü","U")))
